Workbook

Sheet Leia-me
A1: ESTUDO DE VIABILIDADE — KITS DE CAMISETAS BÁSICAS EM MARKETPLACES
A2: Modelo financeiro · Roberto Monte Fusco · Revisão 02 · Edição Blumenau · outubro de 2026
A4: COMO USAR
A5: Passo 1 | B5: Na aba "Ficha de Custo", troque os números AZUIS pelos custos reais da fábrica (malha, facção, aviamentos, embalagem). Todo o resto recalcula.
A6: Passo 2 | B6: Na aba "Premissas", escolha a linha e o tamanho do kit (listas nas células amarelas) e o preço. A "Calculadora" mostra a margem nos quatro canais.
A7: Passo 3 | B7: A aba "Kits 1-3-5-10" mostra, para as 12 combinações de linha e kit, o menor preço com 15% de margem em cada canal e o preço de prateleira sugerido. A conta completa está em "Kits calculo".
A8: Passo 4 | B8: A aba "Tabela de Precos" traz os preços de lançamento propostos; troque um preço e veja a margem de cada canal. "Projecao" projeta 12 meses do kit 3.
A9: Passo 5 | B9: "Benchmark" guarda os 34 preços reais de setembro de 2026 e o Top 10. "Cores" e "Grade de Medidas" calculam o lote de lançamento por cor e tamanho.
A11: LEGENDA DE CORES
A12: Azul | B12: Você edita. É um dado de entrada ou uma premissa.
A13: Preto | B13: Fórmula. Não edite: o modelo se quebra.
A14: Verde | B14: Referência a outra aba desta planilha.
A15: Fundo amarelo | B15: Premissa crítica: um erro aqui distorce todo o resultado.
A16: Fundo verde-claro | B16: Na aba "Frete 2026": valor publicado pelo Mercado Livre. As demais células da tabela são interpolação.
A18: O QUE ESTE MODELO RESPONDE
A19: Margem de contribuição | B19: O que sobra de cada kit depois de CMV (peças + embalagem do kit), comissão, taxa fixa, frete, mídia, imposto e provisão de devolução, antes dos custos fixos.
A20: Piso de 15% | B20: O menor preço, em cada canal, que ainda deixa a margem mínima definida em Premissas!B18, respeitando as faixas de preço de cada plataforma.
A21: Preço sugerido | B21: O próximo preço terminado em 4,90 ou 9,90 acima do piso que mantém a margem mínima.
A22: Custo-alvo | B22: Até quanto a peça pode custar para cada kit empatar com o concorrente de referência e ainda deixar 15%.
A23: Lote de lançamento | B23: 1.200 kits de 3 distribuídos por cor e tamanho, a partir da composição dos kits e da grade de produção.
A24: Equilíbrio e ROAS | B24: Kits por mês para cobrir o custo fixo e o retorno mínimo de mídia para a loja própria não dar prejuízo.
A26: O QUE ELE NÃO RESPONDE
A27: Não é consultoria fiscal | B27: As alíquotas do Simples Nacional são as tabelas públicas de 2026. O enquadramento do CNAE e a decisão sobre IBS e CBS (prazo de cancelamento em 30/11/2026) são do contador.
A28: Não prevê demanda | B28: Os volumes da aba Projecao são premissas de rampa típica, não previsão. Substitua por dados de Nubimetrics e Kalodata.
A29: Custos de fabricação | B29: A Ficha de Custo traz estimativas de mercado calibradas por consumo de malha e preços de atacado de 2026. Não são os custos da fábrica.
A30: Frete do Mercado Livre | B30: Cinco valores da tabela de reputação verde são publicados; os demais foram interpolados. Confira no simulador de custos do painel do vendedor.
A32: O QUE MUDOU DA REV. 01 (AGOSTO) PARA A REV. 02 (OUTUBRO)
B33: • Kits de 1, 3, 5 e 10 peças nas três linhas, com piso de 15% e preço sugerido em cada canal (abas Kits 1-3-5-10 e Kits calculo).
B34: • Embalagem separada: a peça leva só a embalagem individual; cada kit tem sua embalagem de envio e seu peso. Custo da Essencial: R$ 22,06 → R$ 20,52 por peça + embalagem do kit.
B35: • Frete do Mercado Livre pela tabela de reputação verde de 2026, por peso do pacote e faixa de preço (aba Frete 2026), no lugar de R$ 19 fixos.
B36: • Novas abas: Tabela de Precos, Benchmark (34 preços reais e Top 10), Cores (lote por cor e tamanho) e Grade de Medidas.
B37: • Preços terminados em ,90: o kit 3 passa de R$ 169 para R$ 169,90. Projeção e investimento recalculados.

Sheet Premissas
A1: PREMISSAS DO MODELO
A2: Edite apenas as células AZUIS. As amarelas são as que mais mexem no resultado. Ao abrir: Kit 3 da linha Essencial a R$ 169,90.
A4: PRODUTO — KIT EM SIMULAÇÃO NA CALCULADORA
A5: Linha de produto | B5: Essencial | C5: Escolha na lista: Popular, Essencial ou Fibra Longa. Custo, embalagem e peso vêm da Ficha de Custo.
A6: Peças por kit | B6: 3 | C6: Escolha na lista: 1, 3, 5 ou 10.
A7: Índice da linha (1 a 3) | B7: =MATCH(B5,'Ficha de Custo'!$B$4:$D$4,0) -> 2
A8: Custo real por peça (opcional) | C8: Deixe em branco para usar a Ficha de Custo. Preencha com o custo real da fábrica para simular.
A9: Custo por peça aplicado | B9: =IF(ISNUMBER(B8),B8,INDEX('Ficha de Custo'!$B$14:$D$14,B7)) -> 20.52
A10: Embalagem do kit (R$ por pedido) | B10: =IFERROR(INDEX('Ficha de Custo'!$B$18:$D$21,MATCH(B6,'Ficha de Custo'!$A$18:$A$21,0),B7),INDEX('Ficha de Custo'!$B$18:$D$21,MATCH(B6,'Ficha de Custo'!$A$18:$A$21,1),B7)) -> 4.5 | C10: Para kits fora de 1, 3, 5 e 10, usa a embalagem do tamanho padrão imediatamente menor.
A11: Peso da peça (kg) | B11: =INDEX('Ficha de Custo'!$B$15:$D$15,B7) -> 0.2
A12: Peso da embalagem do kit (kg) | B12: =IFERROR(INDEX('Ficha de Custo'!$B$24:$B$27,MATCH(B6,'Ficha de Custo'!$A$24:$A$27,0)),INDEX('Ficha de Custo'!$B$24:$B$27,MATCH(B6,'Ficha de Custo'!$A$24:$A$27,1))) -> 0.08
A13: Peso do pacote (kg) | B13: =ROUND(B6*B11+B12,2) -> 0.68
A14: Faixa de peso (1 = até 0,3 kg … 6 = 2 a 3 kg) | B14: =MATCH(B13-0.0000001,'Frete 2026'!$A$6:$A$11,1) -> 3
A15: Preço de venda do kit | B15: 169.9 | C15: Preço ao consumidor, o mesmo nos quatro canais. Para a tabela por canal, use a aba Tabela de Precos.
A16: CMV do kit | B16: =B9*B6+B10 -> 66.06 | C16: Peças × custo por peça + embalagem do kit.
A17: Preço por peça ao consumidor | B17: =B15/B6 -> 56.633333 | C17: Referências de setembro de 2026: Hering Camiseta Brasil R$ 49,99; Malwee kit 3 R$ 52,33 por peça; Zaroc kit 5 R$ 24,60 por peça.
A18: Margem de contribuição mínima exigida | B18: 0.15 | C18: Abaixo de 15% em moda a operação não sustenta estrutura própria.
A20: COMUM A TODOS OS CANAIS
A21: Simples Nacional — alíquota efetiva | B21: 0.045 | C21: Anexo II (Indústria), 1ª faixa, até R$ 180 mil de receita em 12 meses. Anexo I (Comércio) = 4,0%. Validar com o contador.
A22: Provisão de devolução | B22: 0.05 | C22: Perda líquida com devolução (frete reverso e peça de 2ª). Devolução em moda online: 30% a 40% dos pedidos, mais da metade por tamanho.
A23: Custo fixo mensal da operação | B23: 13000 | C23: Equipe, sistemas, contabilidade, conteúdo. Não inclui pró-labore.
A25: MERCADO LIVRE
A26: Comissão — categoria Moda | B26: 0.14 | C26: Clássico = 14%. Premium = 19% (12x sem juros e mais exposição).
A27: ACOS — Product Ads | B27: 0.06 | C27: Percentual da receita gasto em mídia dentro do ML.
A28: Frete manual (opcional) | C28: Em branco = tabela da aba Frete 2026 pelo peso e pela faixa de preço. Preencha com o valor do seu painel.
A29: Frete aplicado (preço a partir de R$ 79) | B29: =IF(B15<79,0,IF(ISNUMBER(B28),B28,INDEX('Frete 2026'!$C$6:$G$11,B14,MATCH(B15,'Frete 2026'!$C$5:$G$5,1)))) -> 20
A30: Custo logístico manual (opcional) | C30: Em branco = coluna B da aba Frete 2026.
A31: Custo logístico aplicado (preço abaixo de R$ 79) | B31: =IF(B15>=79,0,IF(ISNUMBER(B30),B30,INDEX('Frete 2026'!$B$6:$B$11,B14))) -> 0
A33: SHOPEE
A34: Frete pago pelo vendedor | B34: 0 | C34: Zero no fluxo padrão: desde março de 2026 o Programa de Frete Grátis é obrigatório e está embutido na comissão. Use para a diferença acima do subsídio em pacotes pesados.
A35: ACOS — Shopee Ads | B35: 0.08
A36: Campanha de destaque — adicional | B36: 0 | C36: Use 2,50% se participar de campanha de destaque; 0% caso contrário.
A38: TIKTOK SHOP
A39: Programa de frete grátis | B39: 0.06 | C39: 6% sobre o valor do produto. Inalterado na revisão de 15/07/2026.
A40: Comissão de afiliado | B40: 0.15 | C40: Definida por SKU. Em roupas a prática é de 10% a 20%.
A41: ACOS — anúncios | B41: 0.05
A43: LOJA PRÓPRIA
A44: Gateway de pagamento | B44: 0.0499 | C44: Crédito à vista. Débito costuma ficar perto de 3,99% e parcelado perto de 5,99%.
A45: Gateway — taxa fixa por pedido | B45: 0.39
A46: Frete manual (opcional) | C46: Em branco = coluna H da aba Frete 2026 pelo peso do pacote.
...

Sheet Ficha de Custo
A1: FICHA TÉCNICA DE CUSTO — TRÊS LINHAS DE PRODUTO
A2: Estimativas de mercado calibradas por consumo de malha e preços de atacado de 2026. SUBSTITUA os números azuis pelos da fábrica.
A4: Componente | B4: Popular | C4: Essencial | D4: Fibra Longa | E4: Observação
A5: Composição | B5: PV 67/33 ou cardado · 140 g/m² | C5: 100% algodão penteado 30.1 · 180 g/m² | D5: Pima ou egípcio com laudo · 165 g/m²
A6: Consumo de malha (kg por peça) | B6: 0.175 | C6: 0.215 | D6: 0.2 | E6: Peso da peça acabada mais cerca de 10% de perda de encaixe, na média dos tamanhos M e G. A grade real consome 2,5% a mais (aba Grade de Medidas).
A7: Preço da malha (R$ por kg) | B7: 27 | C7: 48 | D7: 88 | E7: Atacado 2026 (Itajaí e Brusque/SC, Goiânia/GO, Fortaleza/CE). É a variável de maior impacto no custo: confirme com o fornecedor.
A8: Malha | B8: =B6*B7 -> 4.725 | C8: =C6*C7 -> 10.32 | D8: =D6*D7 -> 17.6 | E8: Consumo × preço por quilo.
A9: Gola, ribana e aviamentos | B9: 0.9 | C9: 1.8 | D9: 2.6 | E9: Na Essencial inclui etiqueta tecida.
A10: Facção · corte, costura e acabamento | B10: 4.2 | C10: 7.2 | D10: 9.5 | E10: Se a fábrica tem capacidade ociosa, o custo marginal real é menor. É a pergunta que decide os kits de 5 e 10.
A11: Embalagem individual | B11: 0.3 | C11: 0.6 | D11: 1.2 | E11: Saco e tag (Popular); saco, tag e selo de gramatura (Essencial); papel de seda e tag (Fibra Longa). A embalagem do kit fica no pedido, abaixo.
A12: Perdas e 2ª qualidade (%) | B12: 0.03 | C12: 0.03 | D12: 0.03 | E12: Aplicado sobre a soma dos componentes.
A13: Perdas e 2ª qualidade (R$) | B13: =SUM(B8:B11)*B12 -> 0.30375 | C13: =SUM(C8:C11)*C12 -> 0.5976 | D13: =SUM(D8:D11)*D12 -> 0.927
A14: CUSTO TOTAL POR PEÇA | B14: =ROUND(SUM(B8:B11)+B13,2) -> 10.43 | C14: =ROUND(SUM(C8:C11)+C13,2) -> 20.52 | D14: =ROUND(SUM(D8:D11)+D13,2) -> 31.83 | E14: Arredondado ao centavo: é o valor usado em todo o modelo e na página.
A15: Peso da peça acabada (kg) | B15: 0.16 | C15: 0.2 | D15: 0.19 | E15: Define a faixa de frete do pacote.
A17: EMBALAGEM DO KIT (R$ POR PEDIDO)
A18: 1 | B18: 0.5 | C18: 1.5 | D18: 2.9 | E18: Envelope plástico (Popular) · envelope na avulsa e caixa de papelão com cinta nos kits (Essencial) · caixa rígida (Fibra Longa).
A19: 3 | B19: 0.9 | C19: 4.5 | D19: 7
A20: 5 | B20: 1.1 | C20: 5.5 | D20: 9
A21: 10 | B21: 1.6 | C21: 7.5 | D21: 12
A23: PESO DA EMBALAGEM DO KIT (KG) — IGUAL PARA AS TRÊS LINHAS
A24: 1 | B24: 0.03
A25: 3 | B25: 0.08
A26: 5 | B26: 0.1
A27: 10 | B27: 0.14
A29: CMV DO KIT (R$) = PEÇAS × CUSTO POR PEÇA + EMBALAGEM DO KIT
A30: =A18 -> 1 | B30: =$A30*B$14+B18 -> 10.93 | C30: =$A30*C$14+C18 -> 22.02 | D30: =$A30*D$14+D18 -> 34.73
A31: =A19 -> 3 | B31: =$A31*B$14+B19 -> 32.19 | C31: =$A31*C$14+C19 -> 66.06 | D31: =$A31*D$14+D19 -> 102.49
A32: =A20 -> 5 | B32: =$A32*B$14+B20 -> 53.25 | C32: =$A32*C$14+C20 -> 108.1 | D32: =$A32*D$14+D20 -> 168.15
A33: =A21 -> 10 | B33: =$A33*B$14+B21 -> 105.9 | C33: =$A33*C$14+C21 -> 212.7 | D33: =$A33*D$14+D21 -> 330.3
A35: PESO DO PACOTE (KG) = PEÇAS × PESO DA PEÇA + EMBALAGEM
A36: =A18 -> 1 | B36: =ROUND($A36*B$15+$B$24,2) -> 0.19 | C36: =ROUND($A36*C$15+$B$24,2) -> 0.23 | D36: =ROUND($A36*D$15+$B$24,2) -> 0.22
A37: =A19 -> 3 | B37: =ROUND($A37*B$15+$B$25,2) -> 0.56 | C37: =ROUND($A37*C$15+$B$25,2) -> 0.68 | D37: =ROUND($A37*D$15+$B$25,2) -> 0.65
A38: =A20 -> 5 | B38: =ROUND($A38*B$15+$B$26,2) -> 0.9 | C38: =ROUND($A38*C$15+$B$26,2) -> 1.1 | D38: =ROUND($A38*D$15+$B$26,2) -> 1.05
A39: =A21 -> 10 | B39: =ROUND($A39*B$15+$B$27,2) -> 1.74 | C39: =ROUND($A39*C$15+$B$27,2) -> 2.14 | D39: =ROUND($A39*D$15+$B$27,2) -> 2.04
A41: Capacidade ociosa: se a fábrica já roda com folga, o custo marginal da peça é próximo de malha + aviamentos + embalagem e a margem real sobe de 6 a 9 pontos. Se a fábrica está cheia, o custo de oportunidade é integral e esta ficha está certa.
A42: Rotulagem: no Brasil não há fiscalização efetiva do termo "algodão egípcio". Declarar composição que a peça não tem é publicidade enganosa (CDC) e motivo de remoção de anúncio. Use "algodão egípcio" só com laudo do fornecedor de malha.

Sheet Frete 2026
A1: TABELAS DE FRETE 2026 — MERCADO LIVRE (REPUTAÇÃO VERDE) E LOJA PRÓPRIA
A2: R$ por pacote. Fundo verde-claro = valor publicado; demais = interpolação. Confira no simulador de custos do painel do vendedor.
A4: Peso a partir de (kg) | B4: ML · abaixo de R$ 79 · custo logístico | C4: ML · R$ 79–99,99 | D4: ML · R$ 100–119,99 | E4: ML · R$ 120–149,99 | F4: ML · R$ 150–199,99 | G4: ML · R$ 200+ | H4: Loja própria · frete médio | I4: Faixa de peso
A5: Preço a partir de (R$) → | C5: 79 | D5: 100 | E5: 120 | F5: 150 | G5: 200
A6: 0 | B6: 6.5 | C6: 12.35 | D6: 14.5 | E6: 16.65 | F6: 18.8 | G6: 20.95 | H6: 16 | I6: até 0,3 kg
A7: 0.3 | B7: 6.75 | C7: 12.95 | D7: 15.1 | E7: 17.25 | F7: 19.4 | G7: 21.55 | H7: 17.5 | I7: 0,3 a 0,5 kg
A8: 0.5 | B8: 7 | C8: 13.55 | D8: 15.7 | E8: 17.85 | F8: 20 | G8: 22.15 | H8: 19 | I8: 0,5 a 1 kg
A9: 1 | B9: 7.25 | C9: 16.05 | D9: 18.2 | E9: 20.35 | F9: 22.5 | G9: 24.65 | H9: 22 | I9: 1 a 1,5 kg
A10: 1.5 | B10: 7.5 | C10: 16.05 | D10: 18.2 | E10: 20.35 | F10: 22.5 | G10: 24.65 | H10: 25 | I10: 1,5 a 2 kg
A11: 2 | B11: 8 | C11: 16.75 | D11: 18.9 | E11: 21.05 | F11: 23.2 | G11: 25.35 | H11: 29 | I11: 2 a 3 kg
A13: Publicado (reputação verde): até 0,3 kg, R$ 12,35 entre R$ 79 e R$ 99,99 e R$ 20,95 a partir de R$ 200; 1 a 1,5 kg e 1,5 a 2 kg, R$ 24,65 a partir de R$ 200; 2 a 3 kg, R$ 21,05 para produto de R$ 120. Fontes: Agência X3, GoSmarter, Duoke (março a setembro de 2026). Reputação amarela paga cerca de 20% a mais e a vermelha, o dobro.
A14: Abaixo de R$ 79 o Mercado Livre banca o frete ao comprador e cobra do vendedor um custo operacional por peso (coluna B, estimado a partir dos mínimos publicados de R$ 5,65 a R$ 6,25). A partir de R$ 79 o frete grátis é obrigatório e o vendedor paga a tabela acima. A faixa de peso de um pacote é a primeira cujo limite superior é igual ou maior que o peso: 0,3 kg cai na primeira faixa.
A15: Loja própria: média nacional estimada para envio por Correios ou transportadora via intermediador de frete, por faixa de peso.

Sheet Calculadora
A1: CALCULADORA DE MARGEM POR PLATAFORMA
A2: Tudo aqui é fórmula e vem das abas Premissas e Frete 2026. Para simular, mude os números lá.
A4: Rubrica | B4: Mercado Livre | C4: Shopee | D4: TikTok Shop | E4: Loja própria | F4: Como é calculado
A5: Receita bruta (preço do kit) | B5: =Premissas!$B$15 -> 169.9 | C5: =Premissas!$B$15 -> 169.9 | D5: =Premissas!$B$15 -> 169.9 | E5: =Premissas!$B$15 -> 169.9 | F5: Premissas!B15: mesmo preço em todos os canais, para a comparação ser honesta.
A6: Comissão da plataforma (%) | B6: =Premissas!$B$26 -> 0.14 | C6: =INDEX('Taxas 2026'!$C$15:$C$19,MATCH(C5,'Taxas 2026'!$B$15:$B$19,1))+Premissas!$B$36 -> 0.14 | D6: =INDEX('Taxas 2026'!$C$24:$C$25,MATCH(D5,'Taxas 2026'!$B$24:$B$25,1)) -> 0.06 | E6: =Premissas!$B$44 -> 0.0499 | F6: Shopee e TikTok Shop: faixa de preço das tabelas da aba Taxas 2026 (a Shopee soma a campanha de destaque).
A7: Comissão da plataforma (R$) | B7: =B5*B6 -> 23.786 | C7: =C5*C6 -> 23.786 | D7: =D5*D6 -> 10.194 | E7: =E5*E6+Premissas!$B$45 -> 8.86801 | F7: Na loja própria inclui a taxa fixa do gateway por pedido.
A8: Taxa fixa por item (R$) | B8: =Premissas!$B$31 -> 0 | C8: =INDEX('Taxas 2026'!$D$15:$D$19,MATCH(C5,'Taxas 2026'!$B$15:$B$19,1)) -> 20 | D8: =INDEX('Taxas 2026'!$D$24:$D$25,MATCH(D5,'Taxas 2026'!$B$24:$B$25,1)) -> 6 | E8: =Premissas!$B$48 -> 1.57 | F8: ML: custo logístico por peso, só abaixo de R$ 79. Shopee e TikTok: taxa fixa da faixa. Loja: plataforma e apps por pedido.
A9: Frete (R$) | B9: =Premissas!$B$29 -> 20 | C9: =Premissas!$B$34 -> 0 | D9: =D5*Premissas!$B$39 -> 10.194 | E9: =Premissas!$B$47 -> 19 | F9: ML: tabela verde de 2026 pelo peso do pacote e pela faixa de preço, a partir de R$ 79. TikTok: 6% do programa de frete grátis.
A10: Mídia e afiliados (R$) | B10: =B5*Premissas!$B$27 -> 10.194 | C10: =C5*Premissas!$B$35 -> 13.592 | D10: =D5*(Premissas!$B$40+Premissas!$B$41) -> 33.98 | E10: =E5/Premissas!$B$49 -> 56.633333 | F10: TikTok soma comissão de afiliado e ACOS. Na loja própria, a mídia é o preço dividido pelo ROAS.
A11: Imposto (R$) | B11: =B5*Premissas!$B$21 -> 7.6455 | C11: =C5*Premissas!$B$21 -> 7.6455 | D11: =D5*Premissas!$B$21 -> 7.6455 | E11: =E5*Premissas!$B$21 -> 7.6455
A12: Provisão de devolução (R$) | B12: =B5*Premissas!$B$22 -> 8.495 | C12: =C5*Premissas!$B$22 -> 8.495 | D12: =D5*Premissas!$B$22 -> 8.495 | E12: =E5*Premissas!$B$22 -> 8.495
A13: CMV — peças + embalagem do kit (R$) | B13: =Premissas!$B$16 -> 66.06 | C13: =Premissas!$B$16 -> 66.06 | D13: =Premissas!$B$16 -> 66.06 | E13: =Premissas!$B$16 -> 66.06
A14: TOTAL DE CUSTOS | B14: =SUM(B7:B13) -> 136.1805 | C14: =SUM(C7:C13) -> 139.5785 | D14: =SUM(D7:D13) -> 142.5685 | E14: =SUM(E7:E13) -> 168.27184 | F14: Soma das linhas 7 a 13. A linha 6 é percentual e não entra na soma.
A15: MARGEM DE CONTRIBUIÇÃO (R$) | B15: =B5-B14 -> 33.7195 | C15: =C5-C14 -> 30.3215 | D15: =D5-D14 -> 27.3315 | E15: =E5-E14 -> 1.6281567
A16: MARGEM DE CONTRIBUIÇÃO (%) | B16: =IF(B5=0,0,B15/B5) -> 0.19846675 | C16: =IF(C5=0,0,C15/C5) -> 0.17846675 | D16: =IF(D5=0,0,D15/D5) -> 0.16086816 | E16: =IF(E5=0,0,E15/E5) -> 0.0095830292
A17: Veredito | B17: =IF(B16<0,"PREJUÍZO",IF(B16<Premissas!$B$18,"ABAIXO DO MÍNIMO",IF(B16<0.25,"SAUDÁVEL","FORTE"))) -> SAUDÁVEL | C17: =IF(C16<0,"PREJUÍZO",IF(C16<Premissas!$B$18,"ABAIXO DO MÍNIMO",IF(C16<0.25,"SAUDÁVEL","FORTE"))) -> SAUDÁVEL | D17: =IF(D16<0,"PREJUÍZO",IF(D16<Premissas!$B$18,"ABAIXO DO MÍNIMO",IF(D16<0.25,"SAUDÁVEL","FORTE"))) -> SAUDÁVEL | E17: =IF(E16<0,"PREJUÍZO",IF(E16<Premissas!$B$18,"ABAIXO DO MÍNIMO",IF(E16<0.25,"SAUDÁVEL","FORTE"))) -> ABAIXO DO MÍNIMO
A19: Ponto de equilíbrio (kits por mês) | B19: =IF(B15<=0,"não atinge",ROUNDUP(Premissas!$B$23/B15,0)) -> 386 | C19: =IF(C15<=0,"não atinge",ROUNDUP(Premissas!$B$23/C15,0)) -> 429 | D19: =IF(D15<=0,"não atinge",ROUNDUP(Premissas!$B$23/D15,0)) -> 476 | E19: =IF(E15<=0,"não atinge",ROUNDUP(Premissas!$B$23/E15,0)) -> 7985 | F19: Custo fixo mensal ÷ margem por kit, se todo o volume viesse de um único canal.
A20: Margem antes de mídia (%) | B20: =IF(B5=0,0,(B15+B10)/B5) -> 0.25846675 | C20: =IF(C5=0,0,(C15+C10)/C5) -> 0.25846675 | D20: =IF(D5=0,0,(D15+D10)/D5) -> 0.36086816 | E20: =IF(E5=0,0,(E15+E10)/E5) -> 0.34291636
A21: ROAS de equilíbrio (loja própria) | E21: =IF(E20<=0,"—",1/E20) -> 2.916163 | F21: Inverso da margem antes de mídia. Abaixo disso, cada venda na loja própria dá prejuízo.

Sheet Kits 1-3-5-10
A1: KITS DE 1, 3, 5 E 10 PEÇAS — PISO DE MARGEM E PREÇO SUGERIDO POR CANAL
A2: Piso = menor preço com a margem mínima de Premissas!B18. Sugerido = preço de prateleira terminado em 4,90 ou 9,90. Referências de mercado em azul: setembro de 2026.
A4: Linha | B4: Kit | C4: CMV | D4: Peso (kg) | E4: ML piso | F4: ML sugerido | G4: ML margem | H4: Shopee piso | I4: Shopee sugerido | J4: Shopee margem | K4: TikTok piso | L4: TikTok sugerido | M4: TikTok margem | N4: Loja piso | O4: Loja sugerido | P4: Loja margem | Q4: Piso ML por peça | R4: Referência de mercado | S4: Preço da referência | T4: Piso ML vs. referência | U4: Referência só em loja própria? | V4: Veredito
A5: ='Kits calculo'!A7 -> Popular | B5: ='Kits calculo'!B7 -> 1 | C5: ='Kits calculo'!F7 -> 10.93 | D5: ='Kits calculo'!G7 -> 0.19 | E5: ='Kits calculo'!O7 -> 31.405405 | F5: ='Kits calculo'!R7 -> 34.9 | G5: ='Kits calculo'!S7 -> 0.20557307 | H5: ='Kits calculo'!X7 -> 31.431579 | I5: ='Kits calculo'!AA7 -> 34.9 | J5: ='Kits calculo'!AB7 -> 0.1972063 | K5: ='Kits calculo'!AE7 -> 27.670886 | L5: ='Kits calculo'!AH7 -> 29.9 | M5: ='Kits calculo'!AI7 -> 0.17944816 | N5: ='Kits calculo'!AJ7 -> 77.710033 | O5: ='Kits calculo'!AM7 -> 79.9 | P5: ='Kits calculo'!AN7 -> 0.1601897 | Q5: =E5/B5 -> 31.405405 | R5: Old Rules avulsa (ML) | S5: 33.55 | T5: =IF(ISNUMBER(S5),E5/S5-1,"") -> -0.063922343 | V5: =IF(NOT(ISNUMBER(S5)),"SEM MERCADO",IF(U5="sim","SÓ COM MARCA PRÓPRIA",IF(T5<=0,"COMPETE",IF(T5<=0.05,"NO LIMITE","NÃO COMPETE")))) -> COMPETE
A6: ='Kits calculo'!A8 -> Popular | B6: ='Kits calculo'!B8 -> 3 | C6: ='Kits calculo'!F8 -> 32.19 | D6: ='Kits calculo'!G8 -> 0.56 | E6: ='Kits calculo'!O8 -> 70.612613 | F6: ='Kits calculo'!R8 -> 74.9 | G6: ='Kits calculo'!S8 -> 0.18176903 | H6: ='Kits calculo'!X8 -> 76.189474 | I6: ='Kits calculo'!AA8 -> 79.9 | J6: ='Kits calculo'!AB8 -> 0.17205882 | K6: ='Kits calculo'!AE8 -> 87.793103 | L6: ='Kits calculo'!AH8 -> 89.9 | M6: ='Kits calculo'!AI8 -> 0.16019466 | N6: ='Kits calculo'!AJ8 -> 142.96602 | O6: ='Kits calculo'!AM8 -> 144.9 | P6: ='Kits calculo'!AN8 -> 0.15496197 | Q6: =E6/B6 -> 23.537538 | R6: Old Rules kit 3 lisa (ML) | S6: 69.9 | T6: =IF(ISNUMBER(S6),E6/S6-1,"") -> 0.010194744 | V6: =IF(NOT(ISNUMBER(S6)),"SEM MERCADO",IF(U6="sim","SÓ COM MARCA PRÓPRIA",IF(T6<=0,"COMPETE",IF(T6<=0.05,"NO LIMITE","NÃO COMPETE")))) -> NO LIMITE
A7: ='Kits calculo'!A9 -> Popular | B7: ='Kits calculo'!B9 -> 5 | C7: ='Kits calculo'!F9 -> 53.25 | D7: ='Kits calculo'!G9 -> 0.9 | E7: ='Kits calculo'!O9 -> 128.10811 | F7: ='Kits calculo'!R9 -> 129.9 | G7: ='Kits calculo'!S9 -> 0.15765589 | H7: ='Kits calculo'!X9 -> 136.91589 | I7: ='Kits calculo'!AA9 -> 139.9 | J7: ='Kits calculo'!AB9 -> 0.16141172 | K7: ='Kits calculo'!AE9 -> 136.2069 | L7: ='Kits calculo'!AH9 -> 139.9 | M7: ='Kits calculo'!AI9 -> 0.1614832 | N7: ='Kits calculo'!AJ9 -> 199.61445 | O7: ='Kits calculo'!AM9 -> 199.9 | P7: ='Kits calculo'!AN9 -> 0.15053105 | Q7: =E7/B7 -> 25.621622 | R7: Zaroc kit 5 slim (ML) | S7: 123.01 | T7: =IF(ISNUMBER(S7),E7/S7-1,"") -> 0.041444664 | V7: =IF(NOT(ISNUMBER(S7)),"SEM MERCADO",IF(U7="sim","SÓ COM MARCA PRÓPRIA",IF(T7<=0,"COMPETE",IF(T7<=0.05,"NO LIMITE","NÃO COMPETE")))) -> NO LIMITE
A8: ='Kits calculo'!A10 -> Popular | B8: ='Kits calculo'!B10 -> 10 | C8: ='Kits calculo'!F10 -> 105.9 | D8: ='Kits calculo'!G10 -> 1.74 | E8: ='Kits calculo'!O10 -> 235.22523 | F8: ='Kits calculo'!R10 -> 239.9 | G8: ='Kits calculo'!S10 -> 0.16081492 | H8: ='Kits calculo'!X10 -> 246.54206 | I8: ='Kits calculo'!AA10 -> 249.9 | J8: ='Kits calculo'!AB10 -> 0.15718888 | K8: ='Kits calculo'!AE10 -> 257.24138 | L8: ='Kits calculo'!AH10 -> 259.9 | M8: ='Kits calculo'!AI10 -> 0.15444979 | N8: ='Kits calculo'!AJ10 -> 357.3747 | O8: ='Kits calculo'!AM10 -> 359.9 | P8: ='Kits calculo'!AN10 -> 0.15260857 | Q8: =E8/B8 -> 23.522523 | R8: Old Rules kit 10 (ML) | S8: 224.99 | T8: =IF(ISNUMBER(S8),E8/S8-1,"") -> 0.045491912 | V8: =IF(NOT(ISNUMBER(S8)),"SEM MERCADO",IF(U8="sim","SÓ COM MARCA PRÓPRIA",IF(T8<=0,"COMPETE",IF(T8<=0.05,"NO LIMITE","NÃO COMPETE")))) -> NO LIMITE
A9: ='Kits calculo'!A11 -> Essencial | B9: ='Kits calculo'!B11 -> 1 | C9: ='Kits calculo'!F11 -> 22.02 | D9: ='Kits calculo'!G11 -> 0.23 | E9: ='Kits calculo'!O11 -> 51.387387 | F9: ='Kits calculo'!R11 -> 54.9 | G9: ='Kits calculo'!S11 -> 0.18551002 | H9: ='Kits calculo'!X11 -> 54.778947 | I9: ='Kits calculo'!AA11 -> 54.9 | J9: ='Kits calculo'!AB11 -> 0.15104736 | K9: ='Kits calculo'!AE11 -> 64.413793 | L9: ='Kits calculo'!AH11 -> 64.9 | M9: ='Kits calculo'!AI11 -> 0.15325886 | N9: ='Kits calculo'!AJ11 -> 107.54057 | O9: ='Kits calculo'!AM11 -> 109.9 | P9: ='Kits calculo'!AN11 -> 0.15798141 | Q9: =E9/B9 -> 51.387387 | R9: Hering Camiseta Brasil | S9: 49.99 | T9: =IF(ISNUMBER(S9),E9/S9-1,"") -> 0.027953338 | V9: =IF(NOT(ISNUMBER(S9)),"SEM MERCADO",IF(U9="sim","SÓ COM MARCA PRÓPRIA",IF(T9<=0,"COMPETE",IF(T9<=0.05,"NO LIMITE","NÃO COMPETE")))) -> NO LIMITE
A10: ='Kits calculo'!A12 -> Essencial | B10: ='Kits calculo'!B12 -> 3 | C10: ='Kits calculo'!F12 -> 66.06 | D10: ='Kits calculo'!G12 -> 0.68 | E10: ='Kits calculo'!O12 -> 155.06306 | F10: ='Kits calculo'!R12 -> 159.9 | G10: ='Kits calculo'!S12 -> 0.16678862 | H10: ='Kits calculo'!X12 -> 160.85981 | I10: ='Kits calculo'!AA12 -> 164.9 | J10: ='Kits calculo'!AB12 -> 0.16310794 | K10: ='Kits calculo'!AE12 -> 165.65517 | L10: ='Kits calculo'!AH12 -> 169.9 | M10: ='Kits calculo'!AI12 -> 0.16086816 | N10: ='Kits calculo'!AJ12 -> 234.07155 | O10: ='Kits calculo'!AM12 -> 234.9 | P10: ='Kits calculo'!AN12 -> 0.15131115 | Q10: =E10/B10 -> 51.687688 | R10: Malwee kit 3 (ML) | S10: 156.99 | T10: =IF(ISNUMBER(S10),E10/S10-1,"") -> -0.012274265 | V10: =IF(NOT(ISNUMBER(S10)),"SEM MERCADO",IF(U10="sim","SÓ COM MARCA PRÓPRIA",IF(T10<=0,"COMPETE",IF(T10<=0.05,"NO LIMITE","NÃO COMPETE")))) -> COMPETE
A11: ='Kits calculo'!A13 -> Essencial | B11: ='Kits calculo'!B13 -> 5 | C11: ='Kits calculo'!F13 -> 108.1 | D11: ='Kits calculo'!G13 -> 1.1 | E11: ='Kits calculo'!O13 -> 239.18919 | F11: ='Kits calculo'!R13 -> 239.9 | G11: ='Kits calculo'!S13 -> 0.15164444 | H11: ='Kits calculo'!X13 -> 250.65421 | I11: ='Kits calculo'!AA13 -> 254.9 | J11: ='Kits calculo'!AB13 -> 0.15891134 | K11: ='Kits calculo'!AE13 -> 262.29885 | L11: ='Kits calculo'!AH13 -> 264.9 | M11: ='Kits calculo'!AI13 -> 0.15427142 | N11: ='Kits calculo'!AJ13 -> 355.22281 | O11: ='Kits calculo'!AM13 -> 359.9 | P11: ='Kits calculo'!AN13 -> 0.15483141 | Q11: =E11/B11 -> 47.837838 | R11: Hering kit 5 (ML) | S11: 174.99 | T11: =IF(ISNUMBER(S11),E11/S11-1,"") -> 0.36687347 | V11: =IF(NOT(ISNUMBER(S11)),"SEM MERCADO",IF(U11="sim","SÓ COM MARCA PRÓPRIA",IF(T11<=0,"COMPETE",IF(T11<=0.05,"NO LIMITE","NÃO COMPETE")))) -> NÃO COMPETE
A12: ='Kits calculo'!A14 -> Essencial | B12: ='Kits calculo'!B14 -> 10 | C12: ='Kits calculo'!F14 -> 212.7 | D12: ='Kits calculo'!G14 -> 2.14 | E12: ='Kits calculo'!O14 -> 428.91892 | F12: ='Kits calculo'!R14 -> 429.9 | G12: ='Kits calculo'!S14 -> 0.15126657 | H12: ='Kits calculo'!X14 -> 446.16822 | I12: ='Kits calculo'!AA14 -> 449.9 | J12: ='Kits calculo'!AB14 -> 0.15443765 | K12: ='Kits calculo'!AE14 -> 502.75862 | L12: ='Kits calculo'!AH14 -> 504.9 | M12: ='Kits calculo'!AI14 -> 0.15184492 | N12: ='Kits calculo'!AJ14 -> 655.4111 | O12: ='Kits calculo'!AM14 -> 659.9 | P12: ='Kits calculo'!AN14 -> 0.1525289 | Q12: =E12/B12 -> 42.891892 | R12: Old Rules kit 10 (ML) | S12: 224.99 | T12: =IF(ISNUMBER(S12),E12/S12-1,"") -> 0.90639103 | V12: =IF(NOT(ISNUMBER(S12)),"SEM MERCADO",IF(U12="sim","SÓ COM MARCA PRÓPRIA",IF(T12<=0,"COMPETE",IF(T12<=0.05,"NO LIMITE","NÃO COMPETE")))) -> NÃO COMPETE
A13: ='Kits calculo'!A15 -> Fibra Longa | B13: ='Kits calculo'!B15 -> 1 | C13: ='Kits calculo'!F15 -> 34.73 | D13: ='Kits calculo'!G15 -> 0.22 | E13: ='Kits calculo'!O15 -> 74.288288 | F13: ='Kits calculo'!R15 -> 74.9 | G13: ='Kits calculo'!S15 -> 0.15453271 | H13: ='Kits calculo'!X15 -> 94.82243 | I13: ='Kits calculo'!AA15 -> 94.9 | J13: ='Kits calculo'!AB15 -> 0.1504373 | K13: ='Kits calculo'!AE15 -> 93.632184 | L13: ='Kits calculo'!AH15 -> 94.9 | M13: ='Kits calculo'!AI15 -> 0.15581138 | N13: ='Kits calculo'!AJ15 -> 141.72868 | O13: ='Kits calculo'!AM15 -> 144.9 | P13: ='Kits calculo'!AN15 -> 0.15813658 | Q13: =E13/B13 -> 74.288288 | R13: Insider Tech T-shirt | S13: 135 | T13: =IF(ISNUMBER(S13),E13/S13-1,"") -> -0.44971638 | V13: =IF(NOT(ISNUMBER(S13)),"SEM MERCADO",IF(U13="sim","SÓ COM MARCA PRÓPRIA",IF(T13<=0,"COMPETE",IF(T13<=0.05,"NO LIMITE","NÃO COMPETE")))) -> COMPETE
A14: ='Kits calculo'!A16 -> Fibra Longa | B14: ='Kits calculo'!B16 -> 3 | C14: ='Kits calculo'!F16 -> 102.49 | D14: ='Kits calculo'!G16 -> 0.65 | E14: ='Kits calculo'!O16 -> 224.57658 | F14: ='Kits calculo'!R16 -> 224.9 | G14: ='Kits calculo'!S16 -> 0.15079813 | H14: ='Kits calculo'!X16 -> 240.16822 | I14: ='Kits calculo'!AA16 -> 244.9 | J14: ='Kits calculo'!AB16 -> 0.16033687 | K14: ='Kits calculo'!AE16 -> 249.4023 | L14: ='Kits calculo'!AH16 -> 249.9 | M14: ='Kits calculo'!AI16 -> 0.15086635 | N14: ='Kits calculo'!AJ16 -> 332.06312 | O14: ='Kits calculo'!AM16 -> 334.9 | P14: ='Kits calculo'!AN16 -> 0.15314917 | Q14: =E14/B14 -> 74.858859 | R14: Minimal Club kit 4 → 3 peças | S14: 344.36 | T14: =IF(ISNUMBER(S14),E14/S14-1,"") -> -0.3478436 | V14: =IF(NOT(ISNUMBER(S14)),"SEM MERCADO",IF(U14="sim","SÓ COM MARCA PRÓPRIA",IF(T14<=0,"COMPETE",IF(T14<=0.05,"NO LIMITE","NÃO COMPETE")))) -> COMPETE
A15: ='Kits calculo'!A17 -> Fibra Longa | B15: ='Kits calculo'!B17 -> 5 | C15: ='Kits calculo'!F17 -> 168.15 | D15: ='Kits calculo'!G17 -> 1.05 | E15: ='Kits calculo'!O17 -> 347.38739 | F15: ='Kits calculo'!R17 -> 349.9 | G15: ='Kits calculo'!S17 -> 0.15398542 | H15: ='Kits calculo'!X17 -> 362.8972 | I15: ='Kits calculo'!AA17 -> 364.9 | J15: ='Kits calculo'!AB17 -> 0.15293642 | K15: ='Kits calculo'!AE17 -> 400.34483 | L15: ='Kits calculo'!AH17 -> 404.9 | M15: ='Kits calculo'!AI17 -> 0.1548938 | N15: ='Kits calculo'!AJ17 -> 516.74886 | O15: ='Kits calculo'!AM17 -> 519.9 | P15: ='Kits calculo'!AN17 -> 0.1522533 | Q15: =E15/B15 -> 69.477477 | R15: Minimal Club kit 6 → 5 peças | S15: 638.5 | T15: =IF(ISNUMBER(S15),E15/S15-1,"") -> -0.45593205 | U15: sim | V15: =IF(NOT(ISNUMBER(S15)),"SEM MERCADO",IF(U15="sim","SÓ COM MARCA PRÓPRIA",IF(T15<=0,"COMPETE",IF(T15<=0.05,"NO LIMITE","NÃO COMPETE")))) -> SÓ COM MARCA PRÓPRIA
A16: ='Kits calculo'!A18 -> Fibra Longa | B16: ='Kits calculo'!B18 -> 10 | C16: ='Kits calculo'!F18 -> 330.3 | D16: ='Kits calculo'!G18 -> 2.04 | E16: ='Kits calculo'!O18 -> 640.81081 | F16: ='Kits calculo'!R18 -> 644.9 | G16: ='Kits calculo'!S18 -> 0.15351915 | H16: ='Kits calculo'!X18 -> 665.98131 | I16: ='Kits calculo'!AA18 -> 669.9 | J16: ='Kits calculo'!AB18 -> 0.15312957 | K16: ='Kits calculo'!AE18 -> 773.10345 | L16: ='Kits calculo'!AH18 -> 774.9 | M16: ='Kits calculo'!AI18 -> 0.15100852 | N16: ='Kits calculo'!AJ18 -> 971.73855 | O16: ='Kits calculo'!AM18 -> 974.9 | P16: ='Kits calculo'!AN18 -> 0.15120558 | Q16: =E16/B16 -> 64.081081 | R16: sem referência | T16: =IF(ISNUMBER(S16),E16/S16-1,"") | V16: =IF(NOT(ISNUMBER(S16)),"SEM MERCADO",IF(U16="sim","SÓ COM MARCA PRÓPRIA",IF(T16<=0,"COMPETE",IF(T16<=0.05,"NO LIMITE","NÃO COMPETE")))) -> SEM MERCADO
A18: Veredito: COMPETE = piso abaixo do preço da referência; NO LIMITE = até 5% acima (vender ali significa aceitar menos de 15%); NÃO COMPETE = mais de 5% acima. Nos kits premium de 4 e 6 peças da Minimal Club o preço por peça foi aplicado ao tamanho do kit. Loja própria com mídia paga ao ROAS de Premissas!B49.
A20: CUSTO-ALVO — ATÉ QUANTO A PEÇA PODE CUSTAR PARA EMPATAR COM O CONCORRENTE E DEIXAR A MARGEM MÍNIMA NO ML
A21: Kit | B21: Peças | C21: Referência | D21: Preço | E21: Linha usada | F21: Índice | G21: Embalagem | H21: Peso (kg) | I21: Faixa | J21: Frete ou custo log. | K21: Custo-alvo por peça | L21: Custo da linha | M21: Folga (+) ou falta (−)
A22: Avulsa | B22: 1 | C22: Hering Camiseta Brasil | D22: 49.99 | E22: Essencial | F22: =MATCH(E22,'Ficha de Custo'!$B$4:$D$4,0) -> 2 | G22: =INDEX('Ficha de Custo'!$B$18:$D$21,MATCH(B22,'Ficha de Custo'!$A$18:$A$21,0),F22) -> 1.5 | H22: =INDEX('Ficha de Custo'!$B$36:$D$39,MATCH(B22,'Ficha de Custo'!$A$36:$A$39,0),F22) -> 0.23 | I22: =MATCH(H22-0.0000001,'Frete 2026'!$A$6:$A$11,1) -> 1 | J22: =IF(D22<79,INDEX('Frete 2026'!$B$6:$B$11,I22),INDEX('Frete 2026'!$C$6:$G$11,I22,MATCH(D22,'Frete 2026'!$C$5:$G$5,1))) -> 6.5 | K22: =(D22*(1-Premissas!$B$18)-D22*'Kits calculo'!$D$4-J22-G22)/B22 -> 19.74445 | L22: =INDEX('Ficha de Custo'!$B$14:$D$14,F22) -> 20.52 | M22: =K22-L22 -> -0.77555
A23: Kit 3 | B23: 3 | C23: Malwee kit 3 (ML) | D23: 156.99 | E23: Essencial | F23: =MATCH(E23,'Ficha de Custo'!$B$4:$D$4,0) -> 2 | G23: =INDEX('Ficha de Custo'!$B$18:$D$21,MATCH(B23,'Ficha de Custo'!$A$18:$A$21,0),F23) -> 4.5 | H23: =INDEX('Ficha de Custo'!$B$36:$D$39,MATCH(B23,'Ficha de Custo'!$A$36:$A$39,0),F23) -> 0.68 | I23: =MATCH(H23-0.0000001,'Frete 2026'!$A$6:$A$11,1) -> 3 | J23: =IF(D23<79,INDEX('Frete 2026'!$B$6:$B$11,I23),INDEX('Frete 2026'!$C$6:$G$11,I23,MATCH(D23,'Frete 2026'!$C$5:$G$5,1))) -> 20 | K23: =(D23*(1-Premissas!$B$18)-D23*'Kits calculo'!$D$4-J23-G23)/B23 -> 20.876483 | L23: =INDEX('Ficha de Custo'!$B$14:$D$14,F23) -> 20.52 | M23: =K23-L23 -> 0.35648333
A24: Kit 5 | B24: 5 | C24: Zaroc kit 5 slim (ML) | D24: 123.01 | E24: Popular | F24: =MATCH(E24,'Ficha de Custo'!$B$4:$D$4,0) -> 1 | G24: =INDEX('Ficha de Custo'!$B$18:$D$21,MATCH(B24,'Ficha de Custo'!$A$18:$A$21,0),F24) -> 1.1 | H24: =INDEX('Ficha de Custo'!$B$36:$D$39,MATCH(B24,'Ficha de Custo'!$A$36:$A$39,0),F24) -> 0.9 | I24: =MATCH(H24-0.0000001,'Frete 2026'!$A$6:$A$11,1) -> 3 | J24: =IF(D24<79,INDEX('Frete 2026'!$B$6:$B$11,I24),INDEX('Frete 2026'!$C$6:$G$11,I24,MATCH(D24,'Frete 2026'!$C$5:$G$5,1))) -> 17.85 | K24: =(D24*(1-Premissas!$B$18)-D24*'Kits calculo'!$D$4-J24-G24)/B24 -> 9.86411 | L24: =INDEX('Ficha de Custo'!$B$14:$D$14,F24) -> 10.43 | M24: =K24-L24 -> -0.56589
A25: Kit 10 | B25: 10 | C25: Old Rules kit 10 (ML) | D25: 224.99 | E25: Popular | F25: =MATCH(E25,'Ficha de Custo'!$B$4:$D$4,0) -> 1 | G25: =INDEX('Ficha de Custo'!$B$18:$D$21,MATCH(B25,'Ficha de Custo'!$A$18:$A$21,0),F25) -> 1.6 | H25: =INDEX('Ficha de Custo'!$B$36:$D$39,MATCH(B25,'Ficha de Custo'!$A$36:$A$39,0),F25) -> 1.74 | I25: =MATCH(H25-0.0000001,'Frete 2026'!$A$6:$A$11,1) -> 5 | J25: =IF(D25<79,INDEX('Frete 2026'!$B$6:$B$11,I25),INDEX('Frete 2026'!$C$6:$G$11,I25,MATCH(D25,'Frete 2026'!$C$5:$G$5,1))) -> 24.65 | K25: =(D25*(1-Premissas!$B$18)-D25*'Kits calculo'!$D$4-J25-G25)/B25 -> 9.861945 | L25: =INDEX('Ficha de Custo'!$B$14:$D$14,F25) -> 10.43 | M25: =K25-L25 -> -0.568055

Sheet Kits calculo
A1: MEMÓRIA DE CÁLCULO — PISO DE MARGEM E PREÇO SUGERIDO POR LINHA, KIT E CANAL
A2: Para cada canal, o piso é o menor preço que entrega a margem mínima em alguma faixa de preço da plataforma (colunas "cand."). Não edite: tudo vem de Premissas, Ficha de Custo, Frete 2026 e Taxas 2026.
A4: Margem mínima | B4: =Premissas!$B$18 -> 0.15 | C4: k ML | D4: =Premissas!$B$26+Premissas!$B$27+Premissas!$B$21+Premissas!$B$22 -> 0.295 | E4: k Shopee s/ comissão | F4: =Premissas!$B$36+Premissas!$B$35+Premissas!$B$21+Premissas!$B$22 -> 0.175 | G4: k TikTok s/ comissão | H4: =Premissas!$B$39+Premissas!$B$40+Premissas!$B$41+Premissas!$B$21+Premissas!$B$22 -> 0.355 | I4: k Loja com mídia | J4: =Premissas!$B$44+1/Premissas!$B$49+Premissas!$B$21+Premissas!$B$22 -> 0.47823333 | K4: k Loja sem mídia | L4: =Premissas!$B$44+Premissas!$B$21+Premissas!$B$22 -> 0.1449
A6: Linha | B6: Kit | C6: Índice | D6: Custo/peça | E6: Emb. kit | F6: CMV | G6: Peso (kg) | H6: Faixa peso | I6: ML cand. <79 | J6: ML cand. 79–99 | K6: ML cand. 100–119 | L6: ML cand. 120–149 | M6: ML cand. 150–199 | N6: ML cand. 200+ | O6: ML piso | P6: ML s0 | Q6: ML margem s0 | R6: ML sugerido | S6: ML margem | T6: Shopee cand. 8–79 | U6: Shopee cand. 80–99 | V6: Shopee cand. 100–199 | W6: Shopee cand. 200+ | X6: Shopee piso | Y6: Shopee s0 | Z6: Shopee margem s0 | AA6: Shopee sugerido | AB6: Shopee margem | AC6: TikTok cand. <50 | AD6: TikTok cand. 50+ | AE6: TikTok piso | AF6: TikTok s0 | AG6: TikTok margem s0 | AH6: TikTok sugerido | AI6: TikTok margem | AJ6: Loja piso | AK6: Loja s0 | AL6: Loja margem s0 | AM6: Loja sugerido | AN6: Loja margem
A7: Popular | B7: 1 | C7: =MATCH(A7,'Ficha de Custo'!$B$4:$D$4,0) -> 1 | D7: =INDEX('Ficha de Custo'!$B$14:$D$14,C7) -> 10.43 | E7: =INDEX('Ficha de Custo'!$B$18:$D$21,MATCH(B7,'Ficha de Custo'!$A$18:$A$21,0),C7) -> 0.5 | F7: =D7*B7+E7 -> 10.93 | G7: =INDEX('Ficha de Custo'!$B$36:$D$39,MATCH(B7,'Ficha de Custo'!$A$36:$A$39,0),C7) -> 0.19 | H7: =MATCH(G7-0.0000001,'Frete 2026'!$A$6:$A$11,1) -> 1 | I7: =IF((1-$D$4-$B$4)<=0,"",IF(MAX(1,(F7+INDEX('Frete 2026'!$B$6:$B$11,H7))/(1-$D$4-$B$4))<79,MAX(1,(F7+INDEX('Frete 2026'!$B$6:$B$11,H7))/(1-$D$4-$B$4)),"")) -> 31.405405 | J7: =IF((1-$D$4-$B$4)<=0,"",IF(MAX('Frete 2026'!$C$5,(F7+INDEX('Frete 2026'!$C$6:$C$11,H7))/(1-$D$4-$B$4))<'Frete 2026'!$D$5,MAX('Frete 2026'!$C$5,(F7+INDEX('Frete 2026'!$C$6:$C$11,H7))/(1-$D$4-$B$4)),"")) -> 79 | K7: =IF((1-$D$4-$B$4)<=0,"",IF(MAX('Frete 2026'!$D$5,(F7+INDEX('Frete 2026'!$D$6:$D$11,H7))/(1-$D$4-$B$4))<'Frete 2026'!$E$5,MAX('Frete 2026'!$D$5,(F7+INDEX('Frete 2026'!$D$6:$D$11,H7))/(1-$D$4-$B$4)),"")) -> 100 | L7: =IF((1-$D$4-$B$4)<=0,"",IF(MAX('Frete 2026'!$E$5,(F7+INDEX('Frete 2026'!$E$6:$E$11,H7))/(1-$D$4-$B$4))<'Frete 2026'!$F$5,MAX('Frete 2026'!$E$5,(F7+INDEX('Frete 2026'!$E$6:$E$11,H7))/(1-$D$4-$B$4)),"")) -> 120 | M7: =IF((1-$D$4-$B$4)<=0,"",IF(MAX('Frete 2026'!$F$5,(F7+INDEX('Frete 2026'!$F$6:$F$11,H7))/(1-$D$4-$B$4))<'Frete 2026'!$G$5,MAX('Frete 2026'!$F$5,(F7+INDEX('Frete 2026'!$F$6:$F$11,H7))/(1-$D$4-$B$4)),"")) -> 150 | N7: =IF((1-$D$4-$B$4)<=0,"",IF(MAX('Frete 2026'!$G$5,(F7+INDEX('Frete 2026'!$G$6:$G$11,H7))/(1-$D$4-$B$4))<1000000000,MAX('Frete 2026'!$G$5,(F7+INDEX('Frete 2026'!$G$6:$G$11,H7))/(1-$D$4-$B$4)),"")) -> 200 | O7: =MIN(I7:N7) -> 31.405405 | P7: =CEILING(O7-4.9,5)+4.9 -> 34.9 | Q7: =((P7)-(F7+IF((P7)<79,INDEX('Frete 2026'!$B$6:$B$11,H7),INDEX('Frete 2026'!$C$6:$G$11,H7,MATCH((P7),'Frete 2026'!$C$5:$G$5,1)))+(P7)*$D$4))/(P7) -> 0.20557307 | R7: =IF(((P7)-(F7+IF((P7)<79,INDEX('Frete 2026'!$B$6:$B$11,H7),INDEX('Frete 2026'!$C$6:$G$11,H7,MATCH((P7),'Frete 2026'!$C$5:$G$5,1)))+(P7)*$D$4))/(P7)>=$B$4,P7,IF(((P7+5)-(F7+IF((P7+5)<79,INDEX('Frete 2026'!$B$6:$B$11,H7),INDEX('Frete 2026'!$C$6:$G$11,H7,MATCH((P7+5),'Frete 2026'!$C$5:$G$5,1)))+(P7+5)*$D$4))/(P7+5)>=$B$4,P7+5,P7+10)) -> 34.9 | S7: =((R7)-(F7+IF((R7)<79,INDEX('Frete 2026'!$B$6:$B$11,H7),INDEX('Frete 2026'!$C$6:$G$11,H7,MATCH((R7),'Frete 2026'!$C$5:$G$5,1)))+(R7)*$D$4))/(R7) -> 0.20557307 | T7: =IF((1-'Taxas 2026'!$C$16-$F$4-$B$4)<=0,"",IF(MAX('Taxas 2026'!$B$16,(F7+'Taxas 2026'!$D$16+Premissas!$B$34)/(1-'Taxas 2026'!$C$16-$F$4-$B$4))<'Taxas 2026'!$B$17,MAX('Taxas 2026'!$B$16,(F7+'Taxas 2026'!$D$16+Premissas!$B$34)/(1-'Taxas 2026'!$C$16-$F$4-$B$4)),"")) -> 31.431579 | U7: =IF((1-'Taxas 2026'!$C$17-$F$4-$B$4)<=0,"",IF(MAX('Taxas 2026'!$B$17,(F7+'Taxas 2026'!$D$17+Premissas!$B$34)/(1-'Taxas 2026'!$C$17-$F$4-$B$4))<'Taxas 2026'!$B$18,MAX('Taxas 2026'!$B$17,(F7+'Taxas 2026'!$D$17+Premissas!$B$34)/(1-'Taxas 2026'!$C$17-$F$4-$B$4)),"")) -> 80 | V7: =IF((1-'Taxas 2026'!$C$18-$F$4-$B$4)<=0,"",IF(MAX('Taxas 2026'!$B$18,(F7+'Taxas 2026'!$D$18+Premissas!$B$34)/(1-'Taxas 2026'!$C$18-$F$4-$B$4))<'Taxas 2026'!$B$19,MAX('Taxas 2026'!$B$18,(F7+'Taxas 2026'!$D$18+Premissas!$B$34)/(1-'Taxas 2026'!$C$18-$F$4-$B$4)),"")) -> 100 | W7: =IF((1-'Taxas 2026'!$C$19-$F$4-$B$4)<=0,"",IF(MAX('Taxas 2026'!$B$19,(F7+'Taxas 2026'!$D$19+Premissas!$B$34)/(1-'Taxas 2026'!$C$19-$F$4-$B$4))<1000000000,MAX('Taxas 2026'!$B$19,(F7+'Taxas 2026'!$D$19+Premissas!$B$34)/(1-'Taxas 2026'!$C$19-$F$4-$B$4)),"")) -> 200 | X7: =MIN(T7:W7) -> 31.431579 | Y7: =CEILING(X7-4.9,5)+4.9 -> 34.9 | Z7: =((Y7)-(F7+(Y7)*(INDEX('Taxas 2026'!$C$15:$C$19,MATCH((Y7),'Taxas 2026'!$B$15:$B$19,1))+$F$4)+INDEX('Taxas 2026'!$D$15:$D$19,MATCH((Y7),'Taxas 2026'!$B$15:$B$19,1))+Premissas!$B$34))/(Y7) -> 0.1972063 | AA7: =IF(((Y7)-(F7+(Y7)*(INDEX('Taxas 2026'!$C$15:$C$19,MATCH((Y7),'Taxas 2026'!$B$15:$B$19,1))+$F$4)+INDEX('Taxas 2026'!$D$15:$D$19,MATCH((Y7),'Taxas 2026'!$B$15:$B$19,1))+Premissas!$B$34))/(Y7)>=$B$4,Y7,IF(((Y7+5)-(F7+(Y7+5)*(INDEX('Taxas 2026'!$C$15:$C$19,MATCH((Y7+5),'Taxas 2026'!$B$15:$B$19,1))+$F$4)+INDEX('Taxas 2026'!$D$15:$D$19,MATCH((Y7+5),'Taxas 2026'!$B$15:$B$19,1))+Premissas!$B$34))/(Y7+5)>=$B$4,Y7+5,Y7+10)) -> 34.9 | AB7: =((AA7)-(F7+(AA7)*(INDEX('Taxas 2026'!$C$15:$C$19,MATCH((AA7),'Taxas 2026'!$B$15:$B$19,1))+$F$4)+INDEX('Taxas 2026'!$D$15:$D$19,MATCH((AA7),'Taxas 2026'!$B$15:$B$19,1))+Premissas!$B$34))/(AA7) -> 0.1972063 | AC7: =IF((1-'Taxas 2026'!$C$24-$H$4-$B$4)<=0,"",IF(MAX(1,(F7+'Taxas 2026'!$D$24)/(1-'Taxas 2026'!$C$24-$H$4-$B$4))<'Taxas 2026'!$B$25,MAX(1,(F7+'Taxas 2026'!$D$24)/(1-'Taxas 2026'!$C$24-$H$4-$B$4)),"")) -> 27.670886 | AD7: =IF((1-'Taxas 2026'!$C$25-$H$4-$B$4)<=0,"",IF(MAX('Taxas 2026'!$B$25,(F7+'Taxas 2026'!$D$25)/(1-'Taxas 2026'!$C$25-$H$4-$B$4))<1000000000,MAX('Taxas 2026'!$B$25,(F7+'Taxas 2026'!$D$25)/(1-'Taxas 2026'!$C$25-$H$4-$B$4)),"")) -> 50 | AE7: =MIN(AC7:AD7) -> 27.670886 | AF7: =CEILING(AE7-4.9,5)+4.9 -> 29.9 | AG7: =((AF7)-(F7+(AF7)*(INDEX('Taxas 2026'!$C$24:$C$25,MATCH((AF7),'Taxas 2026'!$B$24:$B$25,1))+$H$4)+INDEX('Taxas 2026'!$D$24:$D$25,MATCH((AF7),'Taxas 2026'!$B$24:$B$25,1))))/(AF7) -> 0.17944816 | AH7: =IF(((AF7)-(F7+(AF7)*(INDEX('Taxas 2026'!$C$24:$C$25,MATCH((AF7),'Taxas 2026'!$B$24:$B$25,1))+$H$4)+INDEX('Taxas 2026'!$D$24:$D$25,MATCH((AF7),'Taxas 2026'!$B$24:$B$25,1))))/(AF7)>=$B$4,AF7,IF(((AF7+5)-(F7+(AF7+5)*(INDEX('Taxas 2026'!$C$24:$C$25,MATCH((AF7+5),'Taxas 2026'!$B$24:$B$25,1))+$H$4)+INDEX('Taxas 2026'!$D$24:$D$25,MATCH((AF7+5),'Taxas 2026'!$B$24:$B$25,1))))/(AF7+5)>=$B$4,AF7+5,AF7+10)) -> 29.9 | AI7: =((AH7)-(F7+(AH7)*(INDEX('Taxas 2026'!$C$24:$C$25,MATCH((AH7),'Taxas 2026'!$B$24:$B$25,1))+$H$4)+INDEX('Taxas 2026'!$D$24:$D$25,MATCH((AH7),'Taxas 2026'!$B$24:$B$25,1))))/(AH7) -> 0.17944816 | AJ7: =MAX(1,(F7+Premissas!$B$45+Premissas!$B$48+INDEX('Frete 2026'!$H$6:$H$11,H7))/(1-$J$4-$B$4)) -> 77.710033 | AK7: =CEILING(AJ7-4.9,5)+4.9 -> 79.9 | AL7: =((AK7)-(F7+Premissas!$B$45+Premissas!$B$48+INDEX('Frete 2026'!$H$6:$H$11,H7)+(AK7)*$J$4))/(AK7) -> 0.1601897 | AM7: =IF(((AK7)-(F7+Premissas!$B$45+Premissas!$B$48+INDEX('Frete 2026'!$H$6:$H$11,H7)+(AK7)*$J$4))/(AK7)>=$B$4,AK7,IF(((AK7+5)-(F7+Premissas!$B$45+Premissas!$B$48+INDEX('Frete 2026'!$H$6:$H$11,H7)+(AK7+5)*$J$4))/(AK7+5)>=$B$4,AK7+5,AK7+10)) -> 79.9 | AN7: =((AM7)-(F7+Premissas!$B$45+Premissas!$B$48+INDEX('Frete 2026'!$H$6:$H$11,H7)+(AM7)*$J$4))/(AM7) -> 0.1601897
A8: Popular | B8: 3 | C8: =MATCH(A8,'Ficha de Custo'!$B$4:$D$4,0) -> 1 | D8: =INDEX('Ficha de Custo'!$B$14:$D$14,C8) -> 10.43 | E8: =INDEX('Ficha de Custo'!$B$18:$D$21,MATCH(B8,'Ficha de Custo'!$A$18:$A$21,0),C8) -> 0.9 | F8: =D8*B8+E8 -> 32.19 | G8: =INDEX('Ficha de Custo'!$B$36:$D$39,MATCH(B8,'Ficha de Custo'!$A$36:$A$39,0),C8) -> 0.56 | H8: =MATCH(G8-0.0000001,'Frete 2026'!$A$6:$A$11,1) -> 3 | I8: =IF((1-$D$4-$B$4)<=0,"",IF(MAX(1,(F8+INDEX('Frete 2026'!$B$6:$B$11,H8))/(1-$D$4-$B$4))<79,MAX(1,(F8+INDEX('Frete 2026'!$B$6:$B$11,H8))/(1-$D$4-$B$4)),"")) -> 70.612613 | J8: =IF((1-$D$4-$B$4)<=0,"",IF(MAX('Frete 2026'!$C$5,(F8+INDEX('Frete 2026'!$C$6:$C$11,H8))/(1-$D$4-$B$4))<'Frete 2026'!$D$5,MAX('Frete 2026'!$C$5,(F8+INDEX('Frete 2026'!$C$6:$C$11,H8))/(1-$D$4-$B$4)),"")) -> 82.414414 | K8: =IF((1-$D$4-$B$4)<=0,"",IF(MAX('Frete 2026'!$D$5,(F8+INDEX('Frete 2026'!$D$6:$D$11,H8))/(1-$D$4-$B$4))<'Frete 2026'!$E$5,MAX('Frete 2026'!$D$5,(F8+INDEX('Frete 2026'!$D$6:$D$11,H8))/(1-$D$4-$B$4)),"")) -> 100 | L8: =IF((1-$D$4-$B$4)<=0,"",IF(MAX('Frete 2026'!$E$5,(F8+INDEX('Frete 2026'!$E$6:$E$11,H8))/(1-$D$4-$B$4))<'Frete 2026'!$F$5,MAX('Frete 2026'!$E$5,(F8+INDEX('Frete 2026'!$E$6:$E$11,H8))/(1-$D$4-$B$4)),"")) -> 120 | M8: =IF((1-$D$4-$B$4)<=0,"",IF(MAX('Frete 2026'!$F$5,(F8+INDEX('Frete 2026'!$F$6:$F$11,H8))/(1-$D$4-$B$4))<'Frete 2026'!$G$5,MAX('Frete 2026'!$F$5,(F8+INDEX('Frete 2026'!$F$6:$F$11,H8))/(1-$D$4-$B$4)),"")) -> 150 | N8: =IF((1-$D$4-$B$4)<=0,"",IF(MAX('Frete 2026'!$G$5,(F8+INDEX('Frete 2026'!$G$6:$G$11,H8))/(1-$D$4-$B$4))<1000000000,MAX('Frete 2026'!$G$5,(F8+INDEX('Frete 2026'!$G$6:$G$11,H8))/(1-$D$4-$B$4)),"")) -> 200 | O8: =MIN(I8:N8) -> 70.612613 | P8: =CEILING(O8-4.9,5)+4.9 -> 74.9 | Q8: =((P8)-(F8+IF((P8)<79,INDEX('Frete 2026'!$B$6:$B$11,H8),INDEX('Frete 2026'!$C$6:$G$11,H8,MATCH((P8),'Frete 2026'!$C$5:$G$5,1)))+(P8)*$D$4))/(P8) -> 0.18176903 | R8: =IF(((P8)-(F8+IF((P8)<79,INDEX('Frete 2026'!$B$6:$B$11,H8),INDEX('Frete 2026'!$C$6:$G$11,H8,MATCH((P8),'Frete 2026'!$C$5:$G$5,1)))+(P8)*$D$4))/(P8)>=$B$4,P8,IF(((P8+5)-(F8+IF((P8+5)<79,INDEX('Frete 2026'!$B$6:$B$11,H8),INDEX('Frete 2026'!$C$6:$G$11,H8,MATCH((P8+5),'Frete 2026'!$C$5:$G$5,1)))+(P8+5)*$D$4))/(P8+5)>=$B$4,P8+5,P8+10)) -> 74.9 | S8: =((R8)-(F8+IF((R8)<79,INDEX('Frete 2026'!$B$6:$B$11,H8),INDEX('Frete 2026'!$C$6:$G$11,H8,MATCH((R8),'Frete 2026'!$C$5:$G$5,1)))+(R8)*$D$4))/(R8) -> 0.18176903 | T8: =IF((1-'Taxas 2026'!$C$16-$F$4-$B$4)<=0,"",IF(MAX('Taxas 2026'!$B$16,(F8+'Taxas 2026'!$D$16+Premissas!$B$34)/(1-'Taxas 2026'!$C$16-$F$4-$B$4))<'Taxas 2026'!$B$17,MAX('Taxas 2026'!$B$16,(F8+'Taxas 2026'!$D$16+Premissas!$B$34)/(1-'Taxas 2026'!$C$16-$F$4-$B$4)),"")) -> 76.189474 | U8: =IF((1-'Taxas 2026'!$C$17-$F$4-$B$4)<=0,"",IF(MAX('Taxas 2026'!$B$17,(F8+'Taxas 2026'!$D$17+Premissas!$B$34)/(1-'Taxas 2026'!$C$17-$F$4-$B$4))<'Taxas 2026'!$B$18,MAX('Taxas 2026'!$B$17,(F8+'Taxas 2026'!$D$17+Premissas!$B$34)/(1-'Taxas 2026'!$C$17-$F$4-$B$4)),"")) -> 90.074766 | V8: =IF((1-'Taxas 2026'!$C$18-$F$4-$B$4)<=0,"",IF(MAX('Taxas 2026'!$B$18,(F8+'Taxas 2026'!$D$18+Premissas!$B$34)/(1-'Taxas 2026'!$C$18-$F$4-$B$4))<'Taxas 2026'!$B$19,MAX('Taxas 2026'!$B$18,(F8+'Taxas 2026'!$D$18+Premissas!$B$34)/(1-'Taxas 2026'!$C$18-$F$4-$B$4)),"")) -> 100 | W8: =IF((1-'Taxas 2026'!$C$19-$F$4-$B$4)<=0,"",IF(MAX('Taxas 2026'!$B$19,(F8+'Taxas 2026'!$D$19+Premissas!$B$34)/(1-'Taxas 2026'!$C$19-$F$4-$B$4))<1000000000,MAX('Taxas 2026'!$B$19,(F8+'Taxas 2026'!$D$19+Premissas!$B$34)/(1-'Taxas 2026'!$C$19-$F$4-$B$4)),"")) -> 200 | X8: =MIN(T8:W8) -> 76.189474 | Y8: =CEILING(X8-4.9,5)+4.9 -> 79.9 | Z8: =((Y8)-(F8+(Y8)*(INDEX('Taxas 2026'!$C$15:$C$19,MATCH((Y8),'Taxas 2026'!$B$15:$B$19,1))+$F$4)+INDEX('Taxas 2026'!$D$15:$D$19,MATCH((Y8),'Taxas 2026'!$B$15:$B$19,1))+Premissas!$B$34))/(Y8) -> 0.17205882 | AA8: =IF(((Y8)-(F8+(Y8)*(INDEX('Taxas 2026'!$C$15:$C$19,MATCH((Y8),'Taxas 2026'!$B$15:$B$19,1))+$F$4)+INDEX('Taxas 2026'!$D$15:$D$19,MATCH((Y8),'Taxas 2026'!$B$15:$B$19,1))+Premissas!$B$34))/(Y8)>=$B$4,Y8,IF(((Y8+5)-(F8+(Y8+5)*(INDEX('Taxas 2026'!$C$15:$C$19,MATCH((Y8+5),'Taxas 2026'!$B$15:$B$19,1))+$F$4)+INDEX('Taxas 2026'!$D$15:$D$19,MATCH((Y8+5),'Taxas 2026'!$B$15:$B$19,1))+Premissas!$B$34))/(Y8+5)>=$B$4,Y8+5,Y8+10)) -> 79.9 | AB8: =((AA8)-(F8+(AA8)*(INDEX('Taxas 2026'!$C$15:$C$19,MATCH((AA8),'Taxas 2026'!$B$15:$B$19,1))+$F$4)+INDEX('Taxas 2026'!$D$15:$D$19,MATCH((AA8),'Taxas 2026'!$B$15:$B$19,1))+Premissas!$B$34))/(AA8) -> 0.17205882 | AC8: =IF((1-'Taxas 2026'!$C$24-$H$4-$B$4)<=0,"",IF(MAX(1,(F8+'Taxas 2026'!$D$24)/(1-'Taxas 2026'!$C$24-$H$4-$B$4))<'Taxas 2026'!$B$25,MAX(1,(F8+'Taxas 2026'!$D$24)/(1-'Taxas 2026'!$C$24-$H$4-$B$4)),"")) | AD8: =IF((1-'Taxas 2026'!$C$25-$H$4-$B$4)<=0,"",IF(MAX('Taxas 2026'!$B$25,(F8+'Taxas 2026'!$D$25)/(1-'Taxas 2026'!$C$25-$H$4-$B$4))<1000000000,MAX('Taxas 2026'!$B$25,(F8+'Taxas 2026'!$D$25)/(1-'Taxas 2026'!$C$25-$H$4-$B$4)),"")) -> 87.793103 | AE8: =MIN(AC8:AD8) -> 87.793103 | AF8: =CEILING(AE8-4.9,5)+4.9 -> 89.9 | AG8: =((AF8)-(F8+(AF8)*(INDEX('Taxas 2026'!$C$24:$C$25,MATCH((AF8),'Taxas 2026'!$B$24:$B$25,1))+$H$4)+INDEX('Taxas 2026'!$D$24:$D$25,MATCH((AF8),'Taxas 2026'!$B$24:$B$25,1))))/(AF8) -> 0.16019466 | AH8: =IF(((AF8)-(F8+(AF8)*(INDEX('Taxas 2026'!$C$24:$C$25,MATCH((AF8),'Taxas 2026'!$B$24:$B$25,1))+$H$4)+INDEX('Taxas 2026'!$D$24:$D$25,MATCH((AF8),'Taxas 2026'!$B$24:$B$25,1))))/(AF8)>=$B$4,AF8,IF(((AF8+5)-(F8+(AF8+5)*(INDEX('Taxas 2026'!$C$24:$C$25,MATCH((AF8+5),'Taxas 2026'!$B$24:$B$25,1))+$H$4)+INDEX('Taxas 2026'!$D$24:$D$25,MATCH((AF8+5),'Taxas 2026'!$B$24:$B$25,1))))/(AF8+5)>=$B$4,AF8+5,AF8+10)) -> 89.9 | AI8: =((AH8)-(F8+(AH8)*(INDEX('Taxas 2026'!$C$24:$C$25,MATCH((AH8),'Taxas 2026'!$B$24:$B$25,1))+$H$4)+INDEX('Taxas 2026'!$D$24:$D$25,MATCH((AH8),'Taxas 2026'!$B$24:$B$25,1))))/(AH8) -> 0.16019466 | AJ8: =MAX(1,(F8+Premissas!$B$45+Premissas!$B$48+INDEX('Frete 2026'!$H$6:$H$11,H8))/(1-$J$4-$B$4)) -> 142.96602 | AK8: =CEILING(AJ8-4.9,5)+4.9 -> 144.9 | AL8: =((AK8)-(F8+Premissas!$B$45+Premissas!$B$48+INDEX('Frete 2026'!$H$6:$H$11,H8)+(AK8)*$J$4))/(AK8) -> 0.15496197 | AM8: =IF(((AK8)-(F8+Premissas!$B$45+Premissas!$B$48+INDEX('Frete 2026'!$H$6:$H$11,H8)+(AK8)*$J$4))/(AK8)>=$B$4,AK8,IF(((AK8+5)-(F8+Premissas!$B$45+Premissas!$B$48+INDEX('Frete 2026'!$H$6:$H$11,H8)+(AK8+5)*$J$4))/(AK8+5)>=$B$4,AK8+5,AK8+10)) -> 144.9 | AN8: =((AM8)-(F8+Premissas!$B$45+Premissas!$B$48+INDEX('Frete 2026'!$H$6:$H$11,H8)+(AM8)*$J$4))/(AM8) -> 0.15496197
A9: Popular | B9: 5 | C9: =MATCH(A9,'Ficha de Custo'!$B$4:$D$4,0) -> 1 | D9: =INDEX('Ficha de Custo'!$B$14:$D$14,C9) -> 10.43 | E9: =INDEX('Ficha de Custo'!$B$18:$D$21,MATCH(B9,'Ficha de Custo'!$A$18:$A$21,0),C9) -> 1.1 | F9: =D9*B9+E9 -> 53.25 | G9: =INDEX('Ficha de Custo'!$B$36:$D$39,MATCH(B9,'Ficha de Custo'!$A$36:$A$39,0),C9) -> 0.9 | H9: =MATCH(G9-0.0000001,'Frete 2026'!$A$6:$A$11,1) -> 3 | I9: =IF((1-$D$4-$B$4)<=0,"",IF(MAX(1,(F9+INDEX('Frete 2026'!$B$6:$B$11,H9))/(1-$D$4-$B$4))<79,MAX(1,(F9+INDEX('Frete 2026'!$B$6:$B$11,H9))/(1-$D$4-$B$4)),"")) | J9: =IF((1-$D$4-$B$4)<=0,"",IF(MAX('Frete 2026'!$C$5,(F9+INDEX('Frete 2026'!$C$6:$C$11,H9))/(1-$D$4-$B$4))<'Frete 2026'!$D$5,MAX('Frete 2026'!$C$5,(F9+INDEX('Frete 2026'!$C$6:$C$11,H9))/(1-$D$4-$B$4)),"")) | K9: =IF((1-$D$4-$B$4)<=0,"",IF(MAX('Frete 2026'!$D$5,(F9+INDEX('Frete 2026'!$D$6:$D$11,H9))/(1-$D$4-$B$4))<'Frete 2026'!$E$5,MAX('Frete 2026'!$D$5,(F9+INDEX('Frete 2026'!$D$6:$D$11,H9))/(1-$D$4-$B$4)),"")) | L9: =IF((1-$D$4-$B$4)<=0,"",IF(MAX('Frete 2026'!$E$5,(F9+INDEX('Frete 2026'!$E$6:$E$11,H9))/(1-$D$4-$B$4))<'Frete 2026'!$F$5,MAX('Frete 2026'!$E$5,(F9+INDEX('Frete 2026'!$E$6:$E$11,H9))/(1-$D$4-$B$4)),"")) -> 128.10811 | M9: =IF((1-$D$4-$B$4)<=0,"",IF(MAX('Frete 2026'!$F$5,(F9+INDEX('Frete 2026'!$F$6:$F$11,H9))/(1-$D$4-$B$4))<'Frete 2026'!$G$5,MAX('Frete 2026'!$F$5,(F9+INDEX('Frete 2026'!$F$6:$F$11,H9))/(1-$D$4-$B$4)),"")) -> 150 | N9: =IF((1-$D$4-$B$4)<=0,"",IF(MAX('Frete 2026'!$G$5,(F9+INDEX('Frete 2026'!$G$6:$G$11,H9))/(1-$D$4-$B$4))<1000000000,MAX('Frete 2026'!$G$5,(F9+INDEX('Frete 2026'!$G$6:$G$11,H9))/(1-$D$4-$B$4)),"")) -> 200 | O9: =MIN(I9:N9) -> 128.10811 | P9: =CEILING(O9-4.9,5)+4.9 -> 129.9 | Q9: =((P9)-(F9+IF((P9)<79,INDEX('Frete 2026'!$B$6:$B$11,H9),INDEX('Frete 2026'!$C$6:$G$11,H9,MATCH((P9),'Frete 2026'!$C$5:$G$5,1)))+(P9)*$D$4))/(P9) -> 0.15765589 | R9: =IF(((P9)-(F9+IF((P9)<79,INDEX('Frete 2026'!$B$6:$B$11,H9),INDEX('Frete 2026'!$C$6:$G$11,H9,MATCH((P9),'Frete 2026'!$C$5:$G$5,1)))+(P9)*$D$4))/(P9)>=$B$4,P9,IF(((P9+5)-(F9+IF((P9+5)<79,INDEX('Frete 2026'!$B$6:$B$11,H9),INDEX('Frete 2026'!$C$6:$G$11,H9,MATCH((P9+5),'Frete 2026'!$C$5:$G$5,1)))+(P9+5)*$D$4))/(P9+5)>=$B$4,P9+5,P9+10)) -> 129.9 | S9: =((R9)-(F9+IF((R9)<79,INDEX('Frete 2026'!$B$6:$B$11,H9),INDEX('Frete 2026'!$C$6:$G$11,H9,MATCH((R9),'Frete 2026'!$C$5:$G$5,1)))+(R9)*$D$4))/(R9) -> 0.15765589 | T9: =IF((1-'Taxas 2026'!$C$16-$F$4-$B$4)<=0,"",IF(MAX('Taxas 2026'!$B$16,(F9+'Taxas 2026'!$D$16+Premissas!$B$34)/(1-'Taxas 2026'!$C$16-$F$4-$B$4))<'Taxas 2026'!$B$17,MAX('Taxas 2026'!$B$16,(F9+'Taxas 2026'!$D$16+Premissas!$B$34)/(1-'Taxas 2026'!$C$16-$F$4-$B$4)),"")) | U9: =IF((1-'Taxas 2026'!$C$17-$F$4-$B$4)<=0,"",IF(MAX('Taxas 2026'!$B$17,(F9+'Taxas 2026'!$D$17+Premissas!$B$34)/(1-'Taxas 2026'!$C$17-$F$4-$B$4))<'Taxas 2026'!$B$18,MAX('Taxas 2026'!$B$17,(F9+'Taxas 2026'!$D$17+Premissas!$B$34)/(1-'Taxas 2026'!$C$17-$F$4-$B$4)),"")) | V9: =IF((1-'Taxas 2026'!$C$18-$F$4-$B$4)<=0,"",IF(MAX('Taxas 2026'!$B$18,(F9+'Taxas 2026'!$D$18+Premissas!$B$34)/(1-'Taxas 2026'!$C$18-$F$4-$B$4))<'Taxas 2026'!$B$19,MAX('Taxas 2026'!$B$18,(F9+'Taxas 2026'!$D$18+Premissas!$B$34)/(1-'Taxas 2026'!$C$18-$F$4-$B$4)),"")) -> 136.91589 | W9: =IF((1-'Taxas 2026'!$C$19-$F$4-$B$4)<=0,"",IF(MAX('Taxas 2026'!$B$19,(F9+'Taxas 2026'!$D$19+Premissas!$B$34)/(1-'Taxas 2026'!$C$19-$F$4-$B$4))<1000000000,MAX('Taxas 2026'!$B$19,(F9+'Taxas 2026'!$D$19+Premissas!$B$34)/(1-'Taxas 2026'!$C$19-$F$4-$B$4)),"")) -> 200 | X9: =MIN(T9:W9) -> 136.91589 | Y9: =CEILING(X9-4.9,5)+4.9 -> 139.9 | Z9: =((Y9)-(F9+(Y9)*(INDEX('Taxas 2026'!$C$15:$C$19,MATCH((Y9),'Taxas 2026'!$B$15:$B$19,1))+$F$4)+INDEX('Taxas 2026'!$D$15:$D$19,MATCH((Y9),'Taxas 2026'!$B$15:$B$19,1))+Premissas!$B$34))/(Y9) -> 0.16141172 | AA9: =IF(((Y9)-(F9+(Y9)*(INDEX('Taxas 2026'!$C$15:$C$19,MATCH((Y9),'Taxas 2026'!$B$15:$B$19,1))+$F$4)+INDEX('Taxas 2026'!$D$15:$D$19,MATCH((Y9),'Taxas 2026'!$B$15:$B$19,1))+Premissas!$B$34))/(Y9)>=$B$4,Y9,IF(((Y9+5)-(F9+(Y9+5)*(INDEX('Taxas 2026'!$C$15:$C$19,MATCH((Y9+5),'Taxas 2026'!$B$15:$B$19,1))+$F$4)+INDEX('Taxas 2026'!$D$15:$D$19,MATCH((Y9+5),'Taxas 2026'!$B$15:$B$19,1))+Premissas!$B$34))/(Y9+5)>=$B$4,Y9+5,Y9+10)) -> 139.9 | AB9: =((AA9)-(F9+(AA9)*(INDEX('Taxas 2026'!$C$15:$C$19,MATCH((AA9),'Taxas 2026'!$B$15:$B$19,1))+$F$4)+INDEX('Taxas 2026'!$D$15:$D$19,MATCH((AA9),'Taxas 2026'!$B$15:$B$19,1))+Premissas!$B$34))/(AA9) -> 0.16141172 | AC9: =IF((1-'Taxas 2026'!$C$24-$H$4-$B$4)<=0,"",IF(MAX(1,(F9+'Taxas 2026'!$D$24)/(1-'Taxas 2026'!$C$24-$H$4-$B$4))<'Taxas 2026'!$B$25,MAX(1,(F9+'Taxas 2026'!$D$24)/(1-'Taxas 2026'!$C$24-$H$4-$B$4)),"")) | AD9: =IF((1-'Taxas 2026'!$C$25-$H$4-$B$4)<=0,"",IF(MAX('Taxas 2026'!$B$25,(F9+'Taxas 2026'!$D$25)/(1-'Taxas 2026'!$C$25-$H$4-$B$4))<1000000000,MAX('Taxas 2026'!$B$25,(F9+'Taxas 2026'!$D$25)/(1-'Taxas 2026'!$C$25-$H$4-$B$4)),"")) -> 136.2069 | AE9: =MIN(AC9:AD9) -> 136.2069 | AF9: =CEILING(AE9-4.9,5)+4.9 -> 139.9 | AG9: =((AF9)-(F9+(AF9)*(INDEX('Taxas 2026'!$C$24:$C$25,MATCH((AF9),'Taxas 2026'!$B$24:$B$25,1))+$H$4)+INDEX('Taxas 2026'!$D$24:$D$25,MATCH((AF9),'Taxas 2026'!$B$24:$B$25,1))))/(AF9) -> 0.1614832 | AH9: =IF(((AF9)-(F9+(AF9)*(INDEX('Taxas 2026'!$C$24:$C$25,MATCH((AF9),'Taxas 2026'!$B$24:$B$25,1))+$H$4)+INDEX('Taxas 2026'!$D$24:$D$25,MATCH((AF9),'Taxas 2026'!$B$24:$B$25,1))))/(AF9)>=$B$4,AF9,IF(((AF9+5)-(F9+(AF9+5)*(INDEX('Taxas 2026'!$C$24:$C$25,MATCH((AF9+5),'Taxas 2026'!$B$24:$B$25,1))+$H$4)+INDEX('Taxas 2026'!$D$24:$D$25,MATCH((AF9+5),'Taxas 2026'!$B$24:$B$25,1))))/(AF9+5)>=$B$4,AF9+5,AF9+10)) -> 139.9 | AI9: =((AH9)-(F9+(AH9)*(INDEX('Taxas 2026'!$C$24:$C$25,MATCH((AH9),'Taxas 2026'!$B$24:$B$25,1))+$H$4)+INDEX('Taxas 2026'!$D$24:$D$25,MATCH((AH9),'Taxas 2026'!$B$24:$B$25,1))))/(AH9) -> 0.1614832 | AJ9: =MAX(1,(F9+Premissas!$B$45+Premissas!$B$48+INDEX('Frete 2026'!$H$6:$H$11,H9))/(1-$J$4-$B$4)) -> 199.61445 | AK9: =CEILING(AJ9-4.9,5)+4.9 -> 199.9 | AL9: =((AK9)-(F9+Premissas!$B$45+Premissas!$B$48+INDEX('Frete 2026'!$H$6:$H$11,H9)+(AK9)*$J$4))/(AK9) -> 0.15053105 | AM9: =IF(((AK9)-(F9+Premissas!$B$45+Premissas!$B$48+INDEX('Frete 2026'!$H$6:$H$11,H9)+(AK9)*$J$4))/(AK9)>=$B$4,AK9,IF(((AK9+5)-(F9+Premissas!$B$45+Premissas!$B$48+INDEX('Frete 2026'!$H$6:$H$11,H9)+(AK9+5)*$J$4))/(AK9+5)>=$B$4,AK9+5,AK9+10)) -> 199.9 | AN9: =((AM9)-(F9+Premissas!$B$45+Premissas!$B$48+INDEX('Frete 2026'!$H$6:$H$11,H9)+(AM9)*$J$4))/(AM9) -> 0.15053105
