Workbook

Sheet Leia-me
A1: ESTUDO DE VIABILIDADE — CANELADO FEMININO EM VENDA DIRETA
A2: Modelo financeiro · Indústria de malharia feminina · 250 mil peças/mês · Revisão 01 · agosto de 2026
A4: COMO USAR
A5: Passo 1 | B5: Abra a aba "Premissas" e substitua os números AZUIS pelos dados reais da fábrica. Comece pelo custo por peça e pelo preço de atacado praticado.
A6: Passo 2 | B6: Confira a aba "Devolução" dentro de Premissas. Em moda feminina esta é a variável que mais destrói margem — não use a estimativa se você já tem o número real.
A7: Passo 3 | B7: A aba "Capacidade" responde à pergunta central: quanto ganha a fábrica inteira ao redirecionar X% da produção para venda direta.
A8: Passo 4 | B8: A aba "Projecao" traz a rampa de 12 meses. Os percentuais de alocação em azul são premissas — troque-os pela capacidade real da célula de logística reversa.
A10: LEGENDA DE CORES
A11: Azul | B11: Você edita. É dado de entrada ou premissa.
A12: Preto | B12: Fórmula. Não edite.
A13: Verde | B13: Referência a outra aba desta planilha.
A14: Fundo amarelo | B14: Premissa crítica: um erro aqui distorce todo o resultado.
A16: O QUE ESTE MODELO RESPONDE
A17: Margem por canal | B17: Quanto sobra por peça em cada canal de venda direta, com o atacado B2B ao lado como linha de base.
A18: Ganho da alocação | B18: Quanto a margem total da fábrica sobe ao redirecionar parte da produção — em reais por mês e em percentual.
A19: Limite operacional | B19: Quantas devoluções por mês a operação precisa processar em cada nível de alocação. É o que limita a velocidade, não a demanda.
A20: ROAS de equilíbrio | B20: O retorno mínimo sobre a verba de mídia para a loja própria não dar prejuízo.
A22: O QUE ELE NÃO RESPONDE
A23: Não é consultoria fiscal | B23: A carga tributária de 14,04% é uma estimativa de Lucro Presumido com ICMS líquido presumido em 7%. O número real depende do estado, do regime especial e do perfil de créditos. A comparação Presumido x Real precisa ser feita pelo contador.
A24: Não prevê demanda | B24: Os percentuais de alocação da aba Projecao são premissas de rampa, não previsão de vendas.
A25: Não mede conflito de canal | B25: O maior risco do projeto — perder um cliente de atacado — não cabe em planilha. Está tratado na aba 06 do estudo em HTML.
A27: FONTES
A28: Plataformas | B28: Mercado Livre: tabela 2026 e mudança de 02/03/2026 na tarifa logística. Shopee: tabela de março/2026 por faixa de preço. TikTok Shop: tabela de 15/07/2026 (6% + R$ 6 acima de R$ 50) e Programa de Frete Grátis a 6%.
A29: Devolução | B29: Taxa de devolução no e-commerce brasileiro de moda em 2026: 30% a 40%, chegando a 50% em vestidos e alfaiataria em algumas operações. Custo de R$ 35 a R$ 65 por devolução.
A30: Tributário | B30: IN RFB 2.306/2026: elevação de 10% nos percentuais de presunção de IRPJ e CSLL sobre a parcela da receita acima de R$ 5 milhões no ano. IN RFB 1.700/2017 para as alíquotas.
A31: Mídia | B31: Repasse de PIS/Cofins e ISS no Meta Ads a partir de 01/01/2026 (+12,15%). Benchmarks de CPM, CPC e ROAS no Brasil em 2026.
A33: Detalhe das tabelas | B33: Ver a aba "Taxas 2026".

Sheet Premissas
A1: PREMISSAS DO MODELO
A2: Edite apenas as células AZUIS. As amarelas são as que mais mexem no resultado.
A4: PEÇA
A5: Custo de fabricação por peça | B5: 29.97 | C5: Vestido canelado midi. SUBSTITUA pelo custo real — ver aba Ficha de Custo.
A6: Preço ao consumidor final | B6: 149 | C6: Preço da venda direta, o mesmo em todos os canais para a comparação ser honesta.
A8: DEVOLUÇÃO — O RISCO DA CATEGORIA
A9: Taxa de devolução | B9: 0.22 | C9: Moda no Brasil fica entre 30% e 40%; em vestidos e alfaiataria chega a 50% em algumas operações. 22% é uma premissa conservadora para malha canelada, que perdoa mais no caimento.
A10: Custo logístico por devolução | B10: 30 | C10: Frete reverso mais recebimento, conferência, higienização e reintegração. O mercado reporta R$ 35 a R$ 65.
A11: Devolvidas que viram 2ª linha | B11: 0.25 | C11: Percentual das peças devolvidas que não voltam ao estoque de 1ª qualidade — perda do CMV.
A12: Provisão de devolução por peça | B12: =B9*(B10+B11*B5) | C12: Taxa × (custo reverso + parcela do CMV perdida). É fixa em reais — por isso pesa muito mais em peça barata.
A14: IMPOSTOS — FORA DO SIMPLES NACIONAL
A15: Tributos federais | B15: 0.0704 | C15: Lucro Presumido: PIS+COFINS 3,65% + IRPJ 2,20% + CSLL 1,19%, já com a elevação de 10% na presunção da IN RFB 2.306/2026.
A16: ICMS líquido de créditos | B16: 0.07 | C16: ESTIMATIVA. Depende do estado, do regime especial e do perfil de créditos. Valide com o contador.
A17: Carga tributária total | B17: =B15+B16 | C17: Com 250 mil peças/mês a empresa está muito acima do teto de R$ 4,8 milhões do Simples — a comparação com pequenos vendedores está errada por cerca de 9 pontos.
A19: CAPACIDADE DA FÁBRICA
A20: Produção mensal | B20: 250000
A21: Alocado à venda direta | B21: 0.05 | C21: Percentual da produção redirecionado. A aba Capacidade mostra o efeito de cada nível.
A23: ATACADO B2B — LINHA DE BASE
A24: Preço de atacado | B24: 52 | C24: O que a fábrica cobra hoje do lojista. É contra este número que toda a venda direta é comparada.
A25: Comissão de representante | B25: 0.05
A26: Frete rateado por peça | B26: 1.2 | C26: Carga fechada, muito menor que o frete unitário do e-commerce.
A27: Devolução B2B | B27: 0.01 | C27: Devolução no atacado é rara e consolidada — nada parecido com o varejo.
A29: MERCADO LIVRE
A30: Comissão — categoria Moda | B30: 0.14 | C30: Clássico 14%. Premium 19%, com 12x sem juros e mais exposição.
A31: Frete líquido do vendedor | B31: 17 | C31: Só se aplica a partir de R$ 79, quando o frete grátis vira obrigatório.
A32: Tarifa logística abaixo de R$ 79 | B32: 6.5 | C32: Desde 02/03/2026 é variável por peso e dimensão.
A33: ACOS — Product Ads | B33: 0.07 | C33: Anúncio novo em moda não sai da página 4 sem mídia.
A35: SHOPEE
A36: Frete pago pelo vendedor | B36: 0 | C36: Zero no fluxo padrão: o Programa de Frete Grátis é obrigatório desde março/2026 e está embutido na comissão.
A37: ACOS — Shopee Ads | B37: 0.08
A39: TIKTOK SHOP
A40: Programa de frete grátis | B40: 0.06 | C40: 6% sobre o valor do produto.
A41: Comissão de afiliado | B41: 0.18 | C41: Em moda feminina a prática é 15% a 20%. É a comissão que GERA a demanda — não é custo desperdiçado.
A42: ACOS — anúncios | B42: 0.05
A44: LOJA PRÓPRIA
A45: Gateway de pagamento | B45: 0.0499 | C45: Crédito à vista.
A46: Gateway — taxa fixa | B46: 0.39
A47: Frete pago pela loja | B47: 17
A48: Plataforma e apps por pedido | B48: 1.2
A49: ROAS da mídia | B49: 3 | C49: Receita dividida pela verba. A mediana de e-commerce em Meta Ads é 1,93x.
...

Sheet Ficha de Custo
A1: FICHA TÉCNICA DE CUSTO — CANELADO FEMININO
A2: Estimativas de mercado calibradas por consumo de malha canelada e preço industrial de 2026. SUBSTITUA pela contabilidade de custos da fábrica.
A4: Componente | B4: Blusa | C4: Saia midi | D4: Vestido midi | E4: Conjunto | F4: Observação
A5: Consumo de malha (kg/peça) | B5: 0.25 | C5: 0.3 | D5: 0.42 | F5: Peso da peça acabada mais perda de encaixe. Canelado a ~280 g/m², tamanho médio M/G.
A6: Preço da malha (R$/kg) | B6: 38 | C6: 38 | D6: 38 | F6: Compra industrial. Lojas de tecido no varejo cobram de R$ 57 a R$ 120/kg — quem compra tonelada não paga isso. Maior alavanca de custo do modelo.
A7: Malha | B7: =B5*B6 | C7: =C5*C6 | D7: =D5*D6
A8: Aviamentos, elastano, etiqueta | B8: 1.4 | C8: 1.2 | D8: 1.9
A9: Facção — corte, costura, acabamento | B9: 7.2 | C9: 6.8 | D9: 9.5 | F9: Se a linha roda com capacidade ociosa, o custo marginal real é menor — ver observação abaixo.
A10: Embalagem | B10: 1.3 | C10: 1.3 | D10: 1.6
A11: Perdas e 2ª qualidade (%) | B11: 0.035 | C11: 0.035 | D11: 0.035
A12: Perdas e 2ª qualidade (R$) | B12: =SUM(B7:B10)*B11 | C12: =SUM(C7:C10)*C11 | D12: =SUM(D7:D10)*D11
A13: CUSTO TOTAL POR PEÇA | B13: =SUM(B7:B10)+B12 | C13: =SUM(C7:C10)+C12 | D13: =SUM(D7:D10)+D12 | E13: =B13+C13 | F13: O conjunto é blusa + saia vendidas como um único SKU: uma venda, um frete, uma devolução.
A15: Preço sugerido ao consumidor | B15: 89 | C15: 99 | D15: 149 | E15: 189
A16: Markup sobre o custo | B16: =B15/B13 | C16: =C15/C13 | D16: =D15/D13 | E16: =E15/E13
A17: Preço de atacado praticado | B17: 35 | C17: 37 | D17: 52 | E17: 73 | F17: O que a fábrica cobra do lojista hoje. A diferença para a linha 15 é o prêmio da venda direta.
A19: DUAS OBSERVAÇÕES QUE MUDAM O RESULTADO
A20: Capacidade ociosa: se a linha já roda com folga, o custo marginal da peça é apenas malha, aviamentos e embalagem — a facção não deveria ser cobrada integralmente. Nesse caso a margem real fica de 5 a 8 pontos acima do que este modelo mostra. Se a fábrica está cheia, o custo de oportunidade é integral e o modelo está correto.
A21: Ticket mínimo: a provisão de devolução é FIXA em reais. Ela pesa 8,7% sobre uma blusa de R$ 89 e 5,5% sobre um vestido de R$ 149. É por isso que a blusa avulsa entrega 14,6% e o conjunto entrega 29,3% — mesma malha, mesma fábrica, margem dobrada.

Sheet Calculadora
A1: MARGEM POR CANAL — COM O ATACADO COMO LINHA DE BASE
A2: Tudo aqui é fórmula e vem da aba Premissas. Para simular, mude os números lá.
A4: Rubrica | B4: Mercado Livre | C4: Shopee | D4: TikTok Shop | E4: Loja própria | F4: Atacado B2B | G4: Como é calculado
A5: Receita bruta | B5: =Premissas!$B$6 | C5: =Premissas!$B$6 | D5: =Premissas!$B$6 | E5: =Premissas!$B$6 | F5: =Premissas!$B$24 | G5: Venda direta: Premissas!B6. Atacado: Premissas!B24.
A6: Comissão (%) | B6: =Premissas!$B$30 | C6: =IF(C$5<8,0.5,IF(C$5<80,0.2,0.14)) | D6: =IF(D$5<50,0.1,0.06) | E6: =Premissas!$B$45 | F6: =Premissas!$B$25 | G6: Shopee: faixa de março/2026. TikTok: 10% abaixo de R$ 50, 6% acima. Atacado: comissão de representante.
A7: Comissão (R$) | B7: =B5*B6 | C7: =C5*C6 | D7: =D5*D6 | E7: =E5*E6+Premissas!$B$46 | F7: =F5*F6
A8: Taxa fixa por item (R$) | B8: =IF(B5<79,Premissas!$B$32,0) | C8: =IF(C5<8,0,IF(C5<80,4,IF(C5<100,16,IF(C5<200,20,26)))) | D8: =IF(D5<50,0,6) | E8: =Premissas!$B$48 | F8: 0
A9: Frete (R$) | B9: =IF(B5>=79,Premissas!$B$31,0) | C9: =Premissas!$B$36 | D9: =D5*Premissas!$B$40 | E9: =Premissas!$B$47 | F9: =Premissas!$B$26 | G9: Atacado usa frete de carga fechada, uma fração do frete unitário do e-commerce.
A10: Mídia e afiliados (R$) | B10: =B5*Premissas!$B$33 | C10: =C5*Premissas!$B$37 | D10: =D5*(Premissas!$B$41+Premissas!$B$42) | E10: =E5/Premissas!$B$49 | F10: 0 | G10: No TikTok, comissão de afiliado + ACOS. Na loja própria, preço dividido pelo ROAS.
A11: Imposto (R$) | B11: =B5*Premissas!$B$17 | C11: =C5*Premissas!$B$17 | D11: =D5*Premissas!$B$17 | E11: =E5*Premissas!$B$17 | F11: =F5*Premissas!$B$17
A12: Provisão de devolução (R$) | B12: =Premissas!$B$12 | C12: =Premissas!$B$12 | D12: =Premissas!$B$12 | E12: =Premissas!$B$12 | F12: =Premissas!$B$27*(Premissas!$B$10*0.4+Premissas!$B$5) | G12: No atacado a devolução é rara e consolidada: 40% do custo reverso unitário e perda integral do CMV.
A13: CMV — custo de fabricação | B13: =Premissas!$B$5 | C13: =Premissas!$B$5 | D13: =Premissas!$B$5 | E13: =Premissas!$B$5 | F13: =Premissas!$B$5
A14: TOTAL DE CUSTOS | B14: =SUM(B7:B13) | C14: =SUM(C7:C13) | D14: =SUM(D7:D13) | E14: =SUM(E7:E13) | F14: =SUM(F7:F13)
A15: MARGEM DE CONTRIBUIÇÃO (R$) | B15: =B5-B14 | C15: =C5-C14 | D15: =D5-D14 | E15: =E5-E14 | F15: =F5-F14
A16: MARGEM DE CONTRIBUIÇÃO (%) | B16: =IF(B5=0,0,B15/B5) | C16: =IF(C5=0,0,C15/C5) | D16: =IF(D5=0,0,D15/D5) | E16: =IF(E5=0,0,E15/E5) | F16: =IF(F5=0,0,F15/F5)
A17: Multiplicador sobre o atacado | B17: =IF($F$15<=0,"—",B15/$F$15) | C17: =IF($F$15<=0,"—",C15/$F$15) | D17: =IF($F$15<=0,"—",D15/$F$15) | E17: =IF($F$15<=0,"—",E15/$F$15) | F17: linha de base | G17: Quantas vezes a margem por peça da venda direta supera a do atacado. É o número que justifica o projeto.
A18: Veredito | B18: =IF(B16<0,"PREJUÍZO",IF(B16<0.20,"APERTADO",IF(B16<0.28,"SAUDÁVEL","FORTE"))) | C18: =IF(C16<0,"PREJUÍZO",IF(C16<0.20,"APERTADO",IF(C16<0.28,"SAUDÁVEL","FORTE"))) | D18: =IF(D16<0,"PREJUÍZO",IF(D16<0.20,"APERTADO",IF(D16<0.28,"SAUDÁVEL","FORTE"))) | E18: =IF(E16<0,"PREJUÍZO",IF(E16<0.20,"APERTADO",IF(E16<0.28,"SAUDÁVEL","FORTE"))) | F18: =IF(F16<0,"PREJUÍZO",IF(F16<0.20,"APERTADO",IF(F16<0.28,"SAUDÁVEL","FORTE")))
A20: Margem antes de mídia (%) | B20: =IF(B5=0,0,(B15+B10)/B5) | C20: =IF(C5=0,0,(C15+C10)/C5) | D20: =IF(D5=0,0,(D15+D10)/D5) | E20: =IF(E5=0,0,(E15+E10)/E5)
A21: ROAS de equilíbrio (loja própria) | E21: =IF(E20<=0,"—",1/E20) | G21: Inverso da margem antes de mídia. Abaixo disso, cada venda na loja própria dá prejuízo. A mediana de mercado é 1,93x.

Sheet Capacidade
A1: ALOCAÇÃO DE CAPACIDADE — A PERGUNTA CENTRAL
A2: Quanto a margem TOTAL da fábrica sobe ao redirecionar parte da produção para venda direta.
A4: MIX DE CANAIS DA VENDA DIRETA
A5: Canal | B5: Mercado Livre | C5: Shopee | D5: TikTok Shop | E5: Loja própria
A6: Participação no mix | B6: 0.45 | C6: 0.25 | D6: 0.2 | E6: 0.1 | F6: =SUM(B6:E6) | G6: ← deve somar 100%
A7: Margem por peça no canal | B7: =Calculadora!$B$15 | C7: =Calculadora!$C$15 | D7: =Calculadora!$D$15 | E7: =Calculadora!$E$15
A8: Margem média ponderada por peça | B8: =SUMPRODUCT(B6:E6,B7:E7) | C8: =Calculadora!$F$15 | D8: ← margem por peça no atacado
A10: CENÁRIOS DE ALOCAÇÃO
A11: Alocação | B11: Peças diretas/mês | C11: Margem venda direta | D11: Margem do atacado | E11: Margem TOTAL | F11: Ganho vs 100% atacado | G11: Devoluções/mês
A12: 0 | B12: =Premissas!$B$20*A12 | C12: =B12*$B$8 | D12: =(Premissas!$B$20-B12)*$C$8 | E12: =C12+D12 | F12: =E12-$E$12 | G12: =B12*Premissas!$B$9
A13: 0.02 | B13: =Premissas!$B$20*A13 | C13: =B13*$B$8 | D13: =(Premissas!$B$20-B13)*$C$8 | E13: =C13+D13 | F13: =E13-$E$12 | G13: =B13*Premissas!$B$9
A14: 0.05 | B14: =Premissas!$B$20*A14 | C14: =B14*$B$8 | D14: =(Premissas!$B$20-B14)*$C$8 | E14: =C14+D14 | F14: =E14-$E$12 | G14: =B14*Premissas!$B$9
A15: 0.1 | B15: =Premissas!$B$20*A15 | C15: =B15*$B$8 | D15: =(Premissas!$B$20-B15)*$C$8 | E15: =C15+D15 | F15: =E15-$E$12 | G15: =B15*Premissas!$B$9
A16: 0.15 | B16: =Premissas!$B$20*A16 | C16: =B16*$B$8 | D16: =(Premissas!$B$20-B16)*$C$8 | E16: =C16+D16 | F16: =E16-$E$12 | G16: =B16*Premissas!$B$9
A17: 0.2 | B17: =Premissas!$B$20*A17 | C17: =B17*$B$8 | D17: =(Premissas!$B$20-B17)*$C$8 | E17: =C17+D17 | F17: =E17-$E$12 | G17: =B17*Premissas!$B$9
A19: ATENÇÃO — o limite do projeto
A20: A coluna "Devoluções/mês" é a restrição real. Cada devolução exige recebimento, conferência, higienização e reintegração ao estoque. Dividido por 21 dias úteis, 2.750 devoluções/mês são cerca de 130 por dia. Amarre a alocação do mês seguinte à capacidade COMPROVADA de processar devoluções do mês corrente — nunca à demanda. Devolução não processada vira reclamação, e reclamação derruba reputação.

Sheet Cenarios
A1: AS QUATRO PEÇAS — MARGEM NO MERCADO LIVRE
A2: Mesma plataforma, mesmas regras. Só mudam custo e preço. Colunas azuis são editáveis.
A4: Peça | B4: Custo | C4: Preço direto | D4: Preço atacado | E4: CMV | F4: Comissão | G4: Frete | H4: Mídia | I4: Imposto | J4: Devolução | K4: Total custos | L4: MC direta | M4: MC % | N4: MC atacado
A5: Blusa canelada | B5: 20.08 | C5: 89 | D5: 35 | E5: =B5 | F5: =C5*Premissas!$B$30 | G5: =IF(C5>=79,Premissas!$B$31,Premissas!$B$32) | H5: =C5*Premissas!$B$33 | I5: =C5*Premissas!$B$17 | J5: =Premissas!$B$9*(Premissas!$B$10+Premissas!$B$11*B5) | K5: =SUM(E5:J5) | L5: =C5-K5 | M5: =IF(C5=0,0,L5/C5) | N5: =D5-B5-D5*Premissas!$B$25-Premissas!$B$26-D5*Premissas!$B$17-Premissas!$B$27*(Premissas!$B$10*0.4+B5)
A6: Saia canelada midi | B6: 21.42 | C6: 99 | D6: 37 | E6: =B6 | F6: =C6*Premissas!$B$30 | G6: =IF(C6>=79,Premissas!$B$31,Premissas!$B$32) | H6: =C6*Premissas!$B$33 | I6: =C6*Premissas!$B$17 | J6: =Premissas!$B$9*(Premissas!$B$10+Premissas!$B$11*B6) | K6: =SUM(E6:J6) | L6: =C6-K6 | M6: =IF(C6=0,0,L6/C6) | N6: =D6-B6-D6*Premissas!$B$25-Premissas!$B$26-D6*Premissas!$B$17-Premissas!$B$27*(Premissas!$B$10*0.4+B6)
A7: Vestido canelado midi | B7: 29.97 | C7: 149 | D7: 52 | E7: =B7 | F7: =C7*Premissas!$B$30 | G7: =IF(C7>=79,Premissas!$B$31,Premissas!$B$32) | H7: =C7*Premissas!$B$33 | I7: =C7*Premissas!$B$17 | J7: =Premissas!$B$9*(Premissas!$B$10+Premissas!$B$11*B7) | K7: =SUM(E7:J7) | L7: =C7-K7 | M7: =IF(C7=0,0,L7/C7) | N7: =D7-B7-D7*Premissas!$B$25-Premissas!$B$26-D7*Premissas!$B$17-Premissas!$B$27*(Premissas!$B$10*0.4+B7)
A8: Conjunto blusa + saia | B8: 41.5 | C8: 189 | D8: 73 | E8: =B8 | F8: =C8*Premissas!$B$30 | G8: =IF(C8>=79,Premissas!$B$31,Premissas!$B$32) | H8: =C8*Premissas!$B$33 | I8: =C8*Premissas!$B$17 | J8: =Premissas!$B$9*(Premissas!$B$10+Premissas!$B$11*B8) | K8: =SUM(E8:J8) | L8: =C8-K8 | M8: =IF(C8=0,0,L8/C8) | N8: =D8-B8-D8*Premissas!$B$25-Premissas!$B$26-D8*Premissas!$B$17-Premissas!$B$27*(Premissas!$B$10*0.4+B8)
A10: Por que a blusa não fecha
A11: A provisão de devolução (coluna J) é praticamente igual nas quatro peças, porque o custo reverso é fixo em reais. Sobre uma blusa de R$ 89 ela pesa quase 9% da receita; sobre um conjunto de R$ 189, menos de 4,5%. É toda a explicação da diferença de margem — e a razão para não anunciar peça avulsa abaixo de R$ 120.

Sheet Sensibilidade
A1: SENSIBILIDADE — MARGEM NO MERCADO LIVRE
A2: Linhas: taxa de devolução. Colunas: preço ao consumidor. Custo de fabricação vem de Premissas!B5.
A3: Custo de fabricação: | B3: =Premissas!$B$5
A5: Devolução ↓ Preço → | B5: 89 | C5: 109 | D5: 129 | E5: 149 | F5: 169 | G5: 189 | H5: 209 | I5: 229
A6: 0.1 | B6: =IF(B$5=0,0,(B$5-B$5*Premissas!$B$30-IF(B$5>=79,Premissas!$B$31,Premissas!$B$32)-B$5*Premissas!$B$33-B$5*Premissas!$B$17-$A6*(Premissas!$B$10+Premissas!$B$11*$B$3)-$B$3)/B$5) | C6: =IF(C$5=0,0,(C$5-C$5*Premissas!$B$30-IF(C$5>=79,Premissas!$B$31,Premissas!$B$32)-C$5*Premissas!$B$33-C$5*Premissas!$B$17-$A6*(Premissas!$B$10+Premissas!$B$11*$B$3)-$B$3)/C$5) | D6: =IF(D$5=0,0,(D$5-D$5*Premissas!$B$30-IF(D$5>=79,Premissas!$B$31,Premissas!$B$32)-D$5*Premissas!$B$33-D$5*Premissas!$B$17-$A6*(Premissas!$B$10+Premissas!$B$11*$B$3)-$B$3)/D$5) | E6: =IF(E$5=0,0,(E$5-E$5*Premissas!$B$30-IF(E$5>=79,Premissas!$B$31,Premissas!$B$32)-E$5*Premissas!$B$33-E$5*Premissas!$B$17-$A6*(Premissas!$B$10+Premissas!$B$11*$B$3)-$B$3)/E$5) | F6: =IF(F$5=0,0,(F$5-F$5*Premissas!$B$30-IF(F$5>=79,Premissas!$B$31,Premissas!$B$32)-F$5*Premissas!$B$33-F$5*Premissas!$B$17-$A6*(Premissas!$B$10+Premissas!$B$11*$B$3)-$B$3)/F$5) | G6: =IF(G$5=0,0,(G$5-G$5*Premissas!$B$30-IF(G$5>=79,Premissas!$B$31,Premissas!$B$32)-G$5*Premissas!$B$33-G$5*Premissas!$B$17-$A6*(Premissas!$B$10+Premissas!$B$11*$B$3)-$B$3)/G$5) | H6: =IF(H$5=0,0,(H$5-H$5*Premissas!$B$30-IF(H$5>=79,Premissas!$B$31,Premissas!$B$32)-H$5*Premissas!$B$33-H$5*Premissas!$B$17-$A6*(Premissas!$B$10+Premissas!$B$11*$B$3)-$B$3)/H$5) | I6: =IF(I$5=0,0,(I$5-I$5*Premissas!$B$30-IF(I$5>=79,Premissas!$B$31,Premissas!$B$32)-I$5*Premissas!$B$33-I$5*Premissas!$B$17-$A6*(Premissas!$B$10+Premissas!$B$11*$B$3)-$B$3)/I$5)
A7: 0.15 | B7: =IF(B$5=0,0,(B$5-B$5*Premissas!$B$30-IF(B$5>=79,Premissas!$B$31,Premissas!$B$32)-B$5*Premissas!$B$33-B$5*Premissas!$B$17-$A7*(Premissas!$B$10+Premissas!$B$11*$B$3)-$B$3)/B$5) | C7: =IF(C$5=0,0,(C$5-C$5*Premissas!$B$30-IF(C$5>=79,Premissas!$B$31,Premissas!$B$32)-C$5*Premissas!$B$33-C$5*Premissas!$B$17-$A7*(Premissas!$B$10+Premissas!$B$11*$B$3)-$B$3)/C$5) | D7: =IF(D$5=0,0,(D$5-D$5*Premissas!$B$30-IF(D$5>=79,Premissas!$B$31,Premissas!$B$32)-D$5*Premissas!$B$33-D$5*Premissas!$B$17-$A7*(Premissas!$B$10+Premissas!$B$11*$B$3)-$B$3)/D$5) | E7: =IF(E$5=0,0,(E$5-E$5*Premissas!$B$30-IF(E$5>=79,Premissas!$B$31,Premissas!$B$32)-E$5*Premissas!$B$33-E$5*Premissas!$B$17-$A7*(Premissas!$B$10+Premissas!$B$11*$B$3)-$B$3)/E$5) | F7: =IF(F$5=0,0,(F$5-F$5*Premissas!$B$30-IF(F$5>=79,Premissas!$B$31,Premissas!$B$32)-F$5*Premissas!$B$33-F$5*Premissas!$B$17-$A7*(Premissas!$B$10+Premissas!$B$11*$B$3)-$B$3)/F$5) | G7: =IF(G$5=0,0,(G$5-G$5*Premissas!$B$30-IF(G$5>=79,Premissas!$B$31,Premissas!$B$32)-G$5*Premissas!$B$33-G$5*Premissas!$B$17-$A7*(Premissas!$B$10+Premissas!$B$11*$B$3)-$B$3)/G$5) | H7: =IF(H$5=0,0,(H$5-H$5*Premissas!$B$30-IF(H$5>=79,Premissas!$B$31,Premissas!$B$32)-H$5*Premissas!$B$33-H$5*Premissas!$B$17-$A7*(Premissas!$B$10+Premissas!$B$11*$B$3)-$B$3)/H$5) | I7: =IF(I$5=0,0,(I$5-I$5*Premissas!$B$30-IF(I$5>=79,Premissas!$B$31,Premissas!$B$32)-I$5*Premissas!$B$33-I$5*Premissas!$B$17-$A7*(Premissas!$B$10+Premissas!$B$11*$B$3)-$B$3)/I$5)
A8: 0.2 | B8: =IF(B$5=0,0,(B$5-B$5*Premissas!$B$30-IF(B$5>=79,Premissas!$B$31,Premissas!$B$32)-B$5*Premissas!$B$33-B$5*Premissas!$B$17-$A8*(Premissas!$B$10+Premissas!$B$11*$B$3)-$B$3)/B$5) | C8: =IF(C$5=0,0,(C$5-C$5*Premissas!$B$30-IF(C$5>=79,Premissas!$B$31,Premissas!$B$32)-C$5*Premissas!$B$33-C$5*Premissas!$B$17-$A8*(Premissas!$B$10+Premissas!$B$11*$B$3)-$B$3)/C$5) | D8: =IF(D$5=0,0,(D$5-D$5*Premissas!$B$30-IF(D$5>=79,Premissas!$B$31,Premissas!$B$32)-D$5*Premissas!$B$33-D$5*Premissas!$B$17-$A8*(Premissas!$B$10+Premissas!$B$11*$B$3)-$B$3)/D$5) | E8: =IF(E$5=0,0,(E$5-E$5*Premissas!$B$30-IF(E$5>=79,Premissas!$B$31,Premissas!$B$32)-E$5*Premissas!$B$33-E$5*Premissas!$B$17-$A8*(Premissas!$B$10+Premissas!$B$11*$B$3)-$B$3)/E$5) | F8: =IF(F$5=0,0,(F$5-F$5*Premissas!$B$30-IF(F$5>=79,Premissas!$B$31,Premissas!$B$32)-F$5*Premissas!$B$33-F$5*Premissas!$B$17-$A8*(Premissas!$B$10+Premissas!$B$11*$B$3)-$B$3)/F$5) | G8: =IF(G$5=0,0,(G$5-G$5*Premissas!$B$30-IF(G$5>=79,Premissas!$B$31,Premissas!$B$32)-G$5*Premissas!$B$33-G$5*Premissas!$B$17-$A8*(Premissas!$B$10+Premissas!$B$11*$B$3)-$B$3)/G$5) | H8: =IF(H$5=0,0,(H$5-H$5*Premissas!$B$30-IF(H$5>=79,Premissas!$B$31,Premissas!$B$32)-H$5*Premissas!$B$33-H$5*Premissas!$B$17-$A8*(Premissas!$B$10+Premissas!$B$11*$B$3)-$B$3)/H$5) | I8: =IF(I$5=0,0,(I$5-I$5*Premissas!$B$30-IF(I$5>=79,Premissas!$B$31,Premissas!$B$32)-I$5*Premissas!$B$33-I$5*Premissas!$B$17-$A8*(Premissas!$B$10+Premissas!$B$11*$B$3)-$B$3)/I$5)
A9: 0.22 | B9: =IF(B$5=0,0,(B$5-B$5*Premissas!$B$30-IF(B$5>=79,Premissas!$B$31,Premissas!$B$32)-B$5*Premissas!$B$33-B$5*Premissas!$B$17-$A9*(Premissas!$B$10+Premissas!$B$11*$B$3)-$B$3)/B$5) | C9: =IF(C$5=0,0,(C$5-C$5*Premissas!$B$30-IF(C$5>=79,Premissas!$B$31,Premissas!$B$32)-C$5*Premissas!$B$33-C$5*Premissas!$B$17-$A9*(Premissas!$B$10+Premissas!$B$11*$B$3)-$B$3)/C$5) | D9: =IF(D$5=0,0,(D$5-D$5*Premissas!$B$30-IF(D$5>=79,Premissas!$B$31,Premissas!$B$32)-D$5*Premissas!$B$33-D$5*Premissas!$B$17-$A9*(Premissas!$B$10+Premissas!$B$11*$B$3)-$B$3)/D$5) | E9: =IF(E$5=0,0,(E$5-E$5*Premissas!$B$30-IF(E$5>=79,Premissas!$B$31,Premissas!$B$32)-E$5*Premissas!$B$33-E$5*Premissas!$B$17-$A9*(Premissas!$B$10+Premissas!$B$11*$B$3)-$B$3)/E$5) | F9: =IF(F$5=0,0,(F$5-F$5*Premissas!$B$30-IF(F$5>=79,Premissas!$B$31,Premissas!$B$32)-F$5*Premissas!$B$33-F$5*Premissas!$B$17-$A9*(Premissas!$B$10+Premissas!$B$11*$B$3)-$B$3)/F$5) | G9: =IF(G$5=0,0,(G$5-G$5*Premissas!$B$30-IF(G$5>=79,Premissas!$B$31,Premissas!$B$32)-G$5*Premissas!$B$33-G$5*Premissas!$B$17-$A9*(Premissas!$B$10+Premissas!$B$11*$B$3)-$B$3)/G$5) | H9: =IF(H$5=0,0,(H$5-H$5*Premissas!$B$30-IF(H$5>=79,Premissas!$B$31,Premissas!$B$32)-H$5*Premissas!$B$33-H$5*Premissas!$B$17-$A9*(Premissas!$B$10+Premissas!$B$11*$B$3)-$B$3)/H$5) | I9: =IF(I$5=0,0,(I$5-I$5*Premissas!$B$30-IF(I$5>=79,Premissas!$B$31,Premissas!$B$32)-I$5*Premissas!$B$33-I$5*Premissas!$B$17-$A9*(Premissas!$B$10+Premissas!$B$11*$B$3)-$B$3)/I$5)
A10: 0.25 | B10: =IF(B$5=0,0,(B$5-B$5*Premissas!$B$30-IF(B$5>=79,Premissas!$B$31,Premissas!$B$32)-B$5*Premissas!$B$33-B$5*Premissas!$B$17-$A10*(Premissas!$B$10+Premissas!$B$11*$B$3)-$B$3)/B$5) | C10: =IF(C$5=0,0,(C$5-C$5*Premissas!$B$30-IF(C$5>=79,Premissas!$B$31,Premissas!$B$32)-C$5*Premissas!$B$33-C$5*Premissas!$B$17-$A10*(Premissas!$B$10+Premissas!$B$11*$B$3)-$B$3)/C$5) | D10: =IF(D$5=0,0,(D$5-D$5*Premissas!$B$30-IF(D$5>=79,Premissas!$B$31,Premissas!$B$32)-D$5*Premissas!$B$33-D$5*Premissas!$B$17-$A10*(Premissas!$B$10+Premissas!$B$11*$B$3)-$B$3)/D$5) | E10: =IF(E$5=0,0,(E$5-E$5*Premissas!$B$30-IF(E$5>=79,Premissas!$B$31,Premissas!$B$32)-E$5*Premissas!$B$33-E$5*Premissas!$B$17-$A10*(Premissas!$B$10+Premissas!$B$11*$B$3)-$B$3)/E$5) | F10: =IF(F$5=0,0,(F$5-F$5*Premissas!$B$30-IF(F$5>=79,Premissas!$B$31,Premissas!$B$32)-F$5*Premissas!$B$33-F$5*Premissas!$B$17-$A10*(Premissas!$B$10+Premissas!$B$11*$B$3)-$B$3)/F$5) | G10: =IF(G$5=0,0,(G$5-G$5*Premissas!$B$30-IF(G$5>=79,Premissas!$B$31,Premissas!$B$32)-G$5*Premissas!$B$33-G$5*Premissas!$B$17-$A10*(Premissas!$B$10+Premissas!$B$11*$B$3)-$B$3)/G$5) | H10: =IF(H$5=0,0,(H$5-H$5*Premissas!$B$30-IF(H$5>=79,Premissas!$B$31,Premissas!$B$32)-H$5*Premissas!$B$33-H$5*Premissas!$B$17-$A10*(Premissas!$B$10+Premissas!$B$11*$B$3)-$B$3)/H$5) | I10: =IF(I$5=0,0,(I$5-I$5*Premissas!$B$30-IF(I$5>=79,Premissas!$B$31,Premissas!$B$32)-I$5*Premissas!$B$33-I$5*Premissas!$B$17-$A10*(Premissas!$B$10+Premissas!$B$11*$B$3)-$B$3)/I$5)
A11: 0.3 | B11: =IF(B$5=0,0,(B$5-B$5*Premissas!$B$30-IF(B$5>=79,Premissas!$B$31,Premissas!$B$32)-B$5*Premissas!$B$33-B$5*Premissas!$B$17-$A11*(Premissas!$B$10+Premissas!$B$11*$B$3)-$B$3)/B$5) | C11: =IF(C$5=0,0,(C$5-C$5*Premissas!$B$30-IF(C$5>=79,Premissas!$B$31,Premissas!$B$32)-C$5*Premissas!$B$33-C$5*Premissas!$B$17-$A11*(Premissas!$B$10+Premissas!$B$11*$B$3)-$B$3)/C$5) | D11: =IF(D$5=0,0,(D$5-D$5*Premissas!$B$30-IF(D$5>=79,Premissas!$B$31,Premissas!$B$32)-D$5*Premissas!$B$33-D$5*Premissas!$B$17-$A11*(Premissas!$B$10+Premissas!$B$11*$B$3)-$B$3)/D$5) | E11: =IF(E$5=0,0,(E$5-E$5*Premissas!$B$30-IF(E$5>=79,Premissas!$B$31,Premissas!$B$32)-E$5*Premissas!$B$33-E$5*Premissas!$B$17-$A11*(Premissas!$B$10+Premissas!$B$11*$B$3)-$B$3)/E$5) | F11: =IF(F$5=0,0,(F$5-F$5*Premissas!$B$30-IF(F$5>=79,Premissas!$B$31,Premissas!$B$32)-F$5*Premissas!$B$33-F$5*Premissas!$B$17-$A11*(Premissas!$B$10+Premissas!$B$11*$B$3)-$B$3)/F$5) | G11: =IF(G$5=0,0,(G$5-G$5*Premissas!$B$30-IF(G$5>=79,Premissas!$B$31,Premissas!$B$32)-G$5*Premissas!$B$33-G$5*Premissas!$B$17-$A11*(Premissas!$B$10+Premissas!$B$11*$B$3)-$B$3)/G$5) | H11: =IF(H$5=0,0,(H$5-H$5*Premissas!$B$30-IF(H$5>=79,Premissas!$B$31,Premissas!$B$32)-H$5*Premissas!$B$33-H$5*Premissas!$B$17-$A11*(Premissas!$B$10+Premissas!$B$11*$B$3)-$B$3)/H$5) | I11: =IF(I$5=0,0,(I$5-I$5*Premissas!$B$30-IF(I$5>=79,Premissas!$B$31,Premissas!$B$32)-I$5*Premissas!$B$33-I$5*Premissas!$B$17-$A11*(Premissas!$B$10+Premissas!$B$11*$B$3)-$B$3)/I$5)
A12: 0.35 | B12: =IF(B$5=0,0,(B$5-B$5*Premissas!$B$30-IF(B$5>=79,Premissas!$B$31,Premissas!$B$32)-B$5*Premissas!$B$33-B$5*Premissas!$B$17-$A12*(Premissas!$B$10+Premissas!$B$11*$B$3)-$B$3)/B$5) | C12: =IF(C$5=0,0,(C$5-C$5*Premissas!$B$30-IF(C$5>=79,Premissas!$B$31,Premissas!$B$32)-C$5*Premissas!$B$33-C$5*Premissas!$B$17-$A12*(Premissas!$B$10+Premissas!$B$11*$B$3)-$B$3)/C$5) | D12: =IF(D$5=0,0,(D$5-D$5*Premissas!$B$30-IF(D$5>=79,Premissas!$B$31,Premissas!$B$32)-D$5*Premissas!$B$33-D$5*Premissas!$B$17-$A12*(Premissas!$B$10+Premissas!$B$11*$B$3)-$B$3)/D$5) | E12: =IF(E$5=0,0,(E$5-E$5*Premissas!$B$30-IF(E$5>=79,Premissas!$B$31,Premissas!$B$32)-E$5*Premissas!$B$33-E$5*Premissas!$B$17-$A12*(Premissas!$B$10+Premissas!$B$11*$B$3)-$B$3)/E$5) | F12: =IF(F$5=0,0,(F$5-F$5*Premissas!$B$30-IF(F$5>=79,Premissas!$B$31,Premissas!$B$32)-F$5*Premissas!$B$33-F$5*Premissas!$B$17-$A12*(Premissas!$B$10+Premissas!$B$11*$B$3)-$B$3)/F$5) | G12: =IF(G$5=0,0,(G$5-G$5*Premissas!$B$30-IF(G$5>=79,Premissas!$B$31,Premissas!$B$32)-G$5*Premissas!$B$33-G$5*Premissas!$B$17-$A12*(Premissas!$B$10+Premissas!$B$11*$B$3)-$B$3)/G$5) | H12: =IF(H$5=0,0,(H$5-H$5*Premissas!$B$30-IF(H$5>=79,Premissas!$B$31,Premissas!$B$32)-H$5*Premissas!$B$33-H$5*Premissas!$B$17-$A12*(Premissas!$B$10+Premissas!$B$11*$B$3)-$B$3)/H$5) | I12: =IF(I$5=0,0,(I$5-I$5*Premissas!$B$30-IF(I$5>=79,Premissas!$B$31,Premissas!$B$32)-I$5*Premissas!$B$33-I$5*Premissas!$B$17-$A12*(Premissas!$B$10+Premissas!$B$11*$B$3)-$B$3)/I$5)
A13: 0.4 | B13: =IF(B$5=0,0,(B$5-B$5*Premissas!$B$30-IF(B$5>=79,Premissas!$B$31,Premissas!$B$32)-B$5*Premissas!$B$33-B$5*Premissas!$B$17-$A13*(Premissas!$B$10+Premissas!$B$11*$B$3)-$B$3)/B$5) | C13: =IF(C$5=0,0,(C$5-C$5*Premissas!$B$30-IF(C$5>=79,Premissas!$B$31,Premissas!$B$32)-C$5*Premissas!$B$33-C$5*Premissas!$B$17-$A13*(Premissas!$B$10+Premissas!$B$11*$B$3)-$B$3)/C$5) | D13: =IF(D$5=0,0,(D$5-D$5*Premissas!$B$30-IF(D$5>=79,Premissas!$B$31,Premissas!$B$32)-D$5*Premissas!$B$33-D$5*Premissas!$B$17-$A13*(Premissas!$B$10+Premissas!$B$11*$B$3)-$B$3)/D$5) | E13: =IF(E$5=0,0,(E$5-E$5*Premissas!$B$30-IF(E$5>=79,Premissas!$B$31,Premissas!$B$32)-E$5*Premissas!$B$33-E$5*Premissas!$B$17-$A13*(Premissas!$B$10+Premissas!$B$11*$B$3)-$B$3)/E$5) | F13: =IF(F$5=0,0,(F$5-F$5*Premissas!$B$30-IF(F$5>=79,Premissas!$B$31,Premissas!$B$32)-F$5*Premissas!$B$33-F$5*Premissas!$B$17-$A13*(Premissas!$B$10+Premissas!$B$11*$B$3)-$B$3)/F$5) | G13: =IF(G$5=0,0,(G$5-G$5*Premissas!$B$30-IF(G$5>=79,Premissas!$B$31,Premissas!$B$32)-G$5*Premissas!$B$33-G$5*Premissas!$B$17-$A13*(Premissas!$B$10+Premissas!$B$11*$B$3)-$B$3)/G$5) | H13: =IF(H$5=0,0,(H$5-H$5*Premissas!$B$30-IF(H$5>=79,Premissas!$B$31,Premissas!$B$32)-H$5*Premissas!$B$33-H$5*Premissas!$B$17-$A13*(Premissas!$B$10+Premissas!$B$11*$B$3)-$B$3)/H$5) | I13: =IF(I$5=0,0,(I$5-I$5*Premissas!$B$30-IF(I$5>=79,Premissas!$B$31,Premissas!$B$32)-I$5*Premissas!$B$33-I$5*Premissas!$B$17-$A13*(Premissas!$B$10+Premissas!$B$11*$B$3)-$B$3)/I$5)
A14: 0.45 | B14: =IF(B$5=0,0,(B$5-B$5*Premissas!$B$30-IF(B$5>=79,Premissas!$B$31,Premissas!$B$32)-B$5*Premissas!$B$33-B$5*Premissas!$B$17-$A14*(Premissas!$B$10+Premissas!$B$11*$B$3)-$B$3)/B$5) | C14: =IF(C$5=0,0,(C$5-C$5*Premissas!$B$30-IF(C$5>=79,Premissas!$B$31,Premissas!$B$32)-C$5*Premissas!$B$33-C$5*Premissas!$B$17-$A14*(Premissas!$B$10+Premissas!$B$11*$B$3)-$B$3)/C$5) | D14: =IF(D$5=0,0,(D$5-D$5*Premissas!$B$30-IF(D$5>=79,Premissas!$B$31,Premissas!$B$32)-D$5*Premissas!$B$33-D$5*Premissas!$B$17-$A14*(Premissas!$B$10+Premissas!$B$11*$B$3)-$B$3)/D$5) | E14: =IF(E$5=0,0,(E$5-E$5*Premissas!$B$30-IF(E$5>=79,Premissas!$B$31,Premissas!$B$32)-E$5*Premissas!$B$33-E$5*Premissas!$B$17-$A14*(Premissas!$B$10+Premissas!$B$11*$B$3)-$B$3)/E$5) | F14: =IF(F$5=0,0,(F$5-F$5*Premissas!$B$30-IF(F$5>=79,Premissas!$B$31,Premissas!$B$32)-F$5*Premissas!$B$33-F$5*Premissas!$B$17-$A14*(Premissas!$B$10+Premissas!$B$11*$B$3)-$B$3)/F$5) | G14: =IF(G$5=0,0,(G$5-G$5*Premissas!$B$30-IF(G$5>=79,Premissas!$B$31,Premissas!$B$32)-G$5*Premissas!$B$33-G$5*Premissas!$B$17-$A14*(Premissas!$B$10+Premissas!$B$11*$B$3)-$B$3)/G$5) | H14: =IF(H$5=0,0,(H$5-H$5*Premissas!$B$30-IF(H$5>=79,Premissas!$B$31,Premissas!$B$32)-H$5*Premissas!$B$33-H$5*Premissas!$B$17-$A14*(Premissas!$B$10+Premissas!$B$11*$B$3)-$B$3)/H$5) | I14: =IF(I$5=0,0,(I$5-I$5*Premissas!$B$30-IF(I$5>=79,Premissas!$B$31,Premissas!$B$32)-I$5*Premissas!$B$33-I$5*Premissas!$B$17-$A14*(Premissas!$B$10+Premissas!$B$11*$B$3)-$B$3)/I$5)
A15: 0.5 | B15: =IF(B$5=0,0,(B$5-B$5*Premissas!$B$30-IF(B$5>=79,Premissas!$B$31,Premissas!$B$32)-B$5*Premissas!$B$33-B$5*Premissas!$B$17-$A15*(Premissas!$B$10+Premissas!$B$11*$B$3)-$B$3)/B$5) | C15: =IF(C$5=0,0,(C$5-C$5*Premissas!$B$30-IF(C$5>=79,Premissas!$B$31,Premissas!$B$32)-C$5*Premissas!$B$33-C$5*Premissas!$B$17-$A15*(Premissas!$B$10+Premissas!$B$11*$B$3)-$B$3)/C$5) | D15: =IF(D$5=0,0,(D$5-D$5*Premissas!$B$30-IF(D$5>=79,Premissas!$B$31,Premissas!$B$32)-D$5*Premissas!$B$33-D$5*Premissas!$B$17-$A15*(Premissas!$B$10+Premissas!$B$11*$B$3)-$B$3)/D$5) | E15: =IF(E$5=0,0,(E$5-E$5*Premissas!$B$30-IF(E$5>=79,Premissas!$B$31,Premissas!$B$32)-E$5*Premissas!$B$33-E$5*Premissas!$B$17-$A15*(Premissas!$B$10+Premissas!$B$11*$B$3)-$B$3)/E$5) | F15: =IF(F$5=0,0,(F$5-F$5*Premissas!$B$30-IF(F$5>=79,Premissas!$B$31,Premissas!$B$32)-F$5*Premissas!$B$33-F$5*Premissas!$B$17-$A15*(Premissas!$B$10+Premissas!$B$11*$B$3)-$B$3)/F$5) | G15: =IF(G$5=0,0,(G$5-G$5*Premissas!$B$30-IF(G$5>=79,Premissas!$B$31,Premissas!$B$32)-G$5*Premissas!$B$33-G$5*Premissas!$B$17-$A15*(Premissas!$B$10+Premissas!$B$11*$B$3)-$B$3)/G$5) | H15: =IF(H$5=0,0,(H$5-H$5*Premissas!$B$30-IF(H$5>=79,Premissas!$B$31,Premissas!$B$32)-H$5*Premissas!$B$33-H$5*Premissas!$B$17-$A15*(Premissas!$B$10+Premissas!$B$11*$B$3)-$B$3)/H$5) | I15: =IF(I$5=0,0,(I$5-I$5*Premissas!$B$30-IF(I$5>=79,Premissas!$B$31,Premissas!$B$32)-I$5*Premissas!$B$33-I$5*Premissas!$B$17-$A15*(Premissas!$B$10+Premissas!$B$11*$B$3)-$B$3)/I$5)
A17: Verde = 25% ou mais. Amarelo = entre 0% e 20%. Vermelho = prejuízo. ATENÇÃO: o custo de fabricação é mantido CONSTANTE em toda a grade, no valor de Premissas!B5 — a grade varia apenas preço e devolução. Para analisar outra peça, troque o custo em Premissas!B5 e a grade inteira se recalcula. A leitura principal é a inclinação: quanto mais baixo o preço, mais cada ponto de devolução dói, porque o custo reverso é fixo em reais.

Sheet Projecao
A1: RAMPA DE 12 MESES
A2: Os percentuais de alocação em azul são premissas de rampa — troque-os pela capacidade real da célula de logística reversa.
A3: Fator de cenário: | B3: 1 | C3: Use 0,60 para o conservador, 1,00 para o base e 1,50 para o agressivo.
A5: Mês | B5: Alocação | C5: Peças diretas | D5: Devoluções | E5: Receita | F5: Margem de contribuição | G5: Custo fixo | H5: Resultado | I5: Acumulado
A6: 1 | B6: 0.005 | C6: =Premissas!$B$20*B6*$B$3 | D6: =C6*Premissas!$B$9 | E6: =C6*Premissas!$B$6 | F6: =C6*Capacidade!$B$8 | G6: =Premissas!$B$52 | H6: =F6-G6 | I6: =H6
A7: 2 | B7: 0.01 | C7: =Premissas!$B$20*B7*$B$3 | D7: =C7*Premissas!$B$9 | E7: =C7*Premissas!$B$6 | F7: =C7*Capacidade!$B$8 | G7: =Premissas!$B$52 | H7: =F7-G7 | I7: =I6+H7
A8: 3 | B8: 0.015 | C8: =Premissas!$B$20*B8*$B$3 | D8: =C8*Premissas!$B$9 | E8: =C8*Premissas!$B$6 | F8: =C8*Capacidade!$B$8 | G8: =Premissas!$B$52 | H8: =F8-G8 | I8: =I7+H8
A9: 4 | B9: 0.02 | C9: =Premissas!$B$20*B9*$B$3 | D9: =C9*Premissas!$B$9 | E9: =C9*Premissas!$B$6 | F9: =C9*Capacidade!$B$8 | G9: =Premissas!$B$52 | H9: =F9-G9 | I9: =I8+H9
A10: 5 | B10: 0.025 | C10: =Premissas!$B$20*B10*$B$3 | D10: =C10*Premissas!$B$9 | E10: =C10*Premissas!$B$6 | F10: =C10*Capacidade!$B$8 | G10: =Premissas!$B$52 | H10: =F10-G10 | I10: =I9+H10
A11: 6 | B11: 0.03 | C11: =Premissas!$B$20*B11*$B$3 | D11: =C11*Premissas!$B$9 | E11: =C11*Premissas!$B$6 | F11: =C11*Capacidade!$B$8 | G11: =Premissas!$B$52 | H11: =F11-G11 | I11: =I10+H11
A12: 7 | B12: 0.035 | C12: =Premissas!$B$20*B12*$B$3 | D12: =C12*Premissas!$B$9 | E12: =C12*Premissas!$B$6 | F12: =C12*Capacidade!$B$8 | G12: =Premissas!$B$52 | H12: =F12-G12 | I12: =I11+H12
A13: 8 | B13: 0.04 | C13: =Premissas!$B$20*B13*$B$3 | D13: =C13*Premissas!$B$9 | E13: =C13*Premissas!$B$6 | F13: =C13*Capacidade!$B$8 | G13: =Premissas!$B$52 | H13: =F13-G13 | I13: =I12+H13
A14: 9 | B14: 0.045 | C14: =Premissas!$B$20*B14*$B$3 | D14: =C14*Premissas!$B$9 | E14: =C14*Premissas!$B$6 | F14: =C14*Capacidade!$B$8 | G14: =Premissas!$B$52 | H14: =F14-G14 | I14: =I13+H14
A15: 10 | B15: 0.05 | C15: =Premissas!$B$20*B15*$B$3 | D15: =C15*Premissas!$B$9 | E15: =C15*Premissas!$B$6 | F15: =C15*Capacidade!$B$8 | G15: =Premissas!$B$52 | H15: =F15-G15 | I15: =I14+H15
A16: 11 | B16: 0.055 | C16: =Premissas!$B$20*B16*$B$3 | D16: =C16*Premissas!$B$9 | E16: =C16*Premissas!$B$6 | F16: =C16*Capacidade!$B$8 | G16: =Premissas!$B$52 | H16: =F16-G16 | I16: =I15+H16
A17: 12 | B17: 0.06 | C17: =Premissas!$B$20*B17*$B$3 | D17: =C17*Premissas!$B$9 | E17: =C17*Premissas!$B$6 | F17: =C17*Capacidade!$B$8 | G17: =Premissas!$B$52 | H17: =F17-G17 | I17: =I16+H17
A18: ANO 1 | C18: =SUM(C6:C17) | D18: =SUM(D6:D17) | E18: =SUM(E6:E17) | F18: =SUM(F6:F17) | G18: =SUM(G6:G17) | H18: =SUM(H6:H17) | I18: =I17
A20: Investimento inicial | C20: =Premissas!$B$53
A21: Mês do equilíbrio operacional | C21: =IF(COUNTIF(H6:H17,">=0")=0,"após o mês 12",13-COUNTIF(H6:H17,">=0")) | D21: Primeiro mês em que a margem cobre o custo fixo da estrutura nova.
A22: Mês em que o caixa cobre o investimento | C22: =IF(COUNTIF(I6:I17,">="&C20)=0,"após o mês 12",13-COUNTIF(I6:I17,">="&C20))
A23: Ganho sobre manter essas peças no atacado | C23: =F18-C18*Capacidade!$C$8 | D23: A diferença de margem nas mesmas peças. É o prêmio de ir direto.

Sheet Midia
A1: CALCULADORA DE MÍDIA — LOJA PRÓPRIA
A2: Meta cobra por impressão; Google cobra por clique. Os dois alimentam o mesmo produto.
A4: ENTRADAS
A5: Ticket médio | B5: =Premissas!$B$6 | C5: Vem de Premissas!B6.
A6: Margem antes de mídia (%) | B6: =Calculadora!$E$20 | C6: Vem da Calculadora — loja própria, antes do custo de aquisição.
A7: Verba mensal total | B7: 40000
A8: Split da verba para Meta | B8: 0.7 | C8: O restante vai para o Google.
A9: CPM — Meta | B9: 26 | C9: Moda feminina no Brasil em 2026: feed entre R$ 15 e R$ 35; Reels entre R$ 8 e R$ 20.
A10: CTR — Meta | B10: 0.018
A11: Conversão — Meta | B11: 0.017 | C11: A variável mais decisiva de todo o bloco.
A12: CPC — Google | B12: 2.8 | C12: E-commerce de moda no Brasil: R$ 1,50 a R$ 4,00.
A13: Conversão — Google | B13: 0.024 | C13: A busca converte melhor porque a intenção já existe.
A14: Taxa de recompra em 12 meses | B14: 0.38 | C14: Sem retenção estruturada: 15% a 25%. Com fidelidade e e-mail: 35% a 50%.
A15: Pedidos extras por recompradora | B15: 1.6
A17: RESULTADO
A18: Margem de contribuição por pedido | B18: =B5*B6 | C18: Antes do custo de mídia.
A19: ROAS de equilíbrio | B19: =IF(B6<=0,"—",1/B6) | C19: Abaixo disso a mídia não se paga. Mediana de e-commerce em Meta Ads: 1,93x.
A20: Verba — Meta | B20: =B7*B8
A21: Verba — Google | B21: =B7-B20
A22: Impressões — Meta | B22: =IF(B9=0,0,B20/B9*1000)
A23: Cliques — Meta | B23: =B22*B10
A24: Pedidos — Meta | B24: =B23*B11
A25: Cliques — Google | B25: =IF(B12=0,0,B21/B12)
A26: Pedidos — Google | B26: =B25*B13
A27: Pedidos totais | B27: =B24+B26
A28: CAC médio | B28: =IF(B27=0,"—",B7/B27) | C28: No varejo online o CAC subiu cerca de 35% em três anos.
A29: Receita gerada | B29: =B27*B5
A30: ROAS realizado | B30: =IF(B7=0,0,B29/B7)
A31: Resultado após mídia | B31: =B27*B18-B7 | C31: Negativo significa que a primeira compra não paga a aquisição.
A32: LTV em 12 meses | B32: =B18*(1+B14*B15)
A33: LTV ÷ CAC | B33: =IF(OR(B27=0,B7=0),"—",B32/(B7/B27)) | C33: A regra de mercado é no mínimo 3,0x.
A35: Veredito | B35: =IF(B31>=0,"A mídia se paga na primeira compra","A mídia NÃO se paga na primeira compra")
A36: Leitura | B36: =IF(B33>=3,"Relação LTV/CAC saudável: a base financia a próxima safra.","Com este CAC o caminho não é mídia fria — é usar marketplace e TikTok Shop para adquirir a cliente, e a loja própria para a recompra.")

Sheet Taxas 2026
A1: TABELAS DE REFERÊNCIA — VIGENTES EM AGOSTO DE 2026
A2: Consulta. Nada aqui alimenta o modelo automaticamente — as premissas ficam na aba Premissas.
A4: MERCADO LIVRE — CATEGORIA MODA
A5: Tipo de anúncio | B5: Comissão | C5: Custo adicional | D5: Observação
A6: Clássico | B6: 0.14 | C6: — | D6: Menor taxa, menor exposição.
A7: Premium | B7: 0.19 | C7: — | D7: 12x sem juros e mais exposição na busca.
A8: Preço abaixo de R$ 79 | B8: — | C8: variável | D8: Desde 02/03/2026 a taxa fixa virou custo logístico variável por peso e dimensão.
A9: Preço a partir de R$ 79 | B9: — | C9: frete grátis | D9: Frete grátis obrigatório; o ML subsidia parte conforme a reputação. Sem custo fixo por unidade.
A10: A tarifa logística passou a incidir em toda venda, independentemente de quem paga o frete. Armazenagem no Full ficou 7,6% mais cara.
A12: SHOPEE — TABELA DE MARÇO DE 2026
A13: Faixa de preço | B13: Comissão | C13: Taxa fixa por item | D13: Observação
A14: Abaixo de R$ 8 | B14: 0.5 | C14: 0 | D14: Faixa punitiva.
A15: De R$ 8 a R$ 79,99 | B15: 0.2 | C15: 4 | D15: A pior faixa para ticket baixo.
A16: De R$ 80 a R$ 99,99 | B16: 0.14 | C16: 16 | D16: A comissão cai, mas a taxa fixa sobe muito.
A17: De R$ 100 a R$ 199,99 | B17: 0.14 | C17: 20 | D17: Faixa recomendada para vestido e conjunto.
A18: R$ 200 ou mais | B18: 0.14 | C18: 26 | D18: —
A19: O teto de comissão de R$ 100 por item foi extinto e a taxa fixa subiu até 550%. O Programa de Frete Grátis deixou de ser opcional.
A21: TIKTOK SHOP — TABELA DE 15 DE JULHO DE 2026
A22: Faixa de preço | B22: Comissão | C22: Taxa fixa por item | D22: Observação
A23: Abaixo de R$ 50 | B23: 0.1 | C23: 0 | D23: A comissão subiu de 6% para 10% nesta faixa.
A24: R$ 50 ou mais | B24: 0.06 | C24: 6 | D24: A taxa fixa subiu de R$ 4 para R$ 6.
A25: Programa de frete grátis | B25: 0.06 | C25: — | D25: Sobre o valor do produto.
A26: Comissão de afiliado | B26: 15% a 20% | C26: — | D26: Definida por SKU. Em moda feminina a prática fica entre 15% e 20%.
A27: Menor taxa de plataforma das três, mas a demanda não vem incluída: a comissão de afiliado é, na prática, o custo de gerar a demanda — e só se paga quando vende.
A29: TRIBUTAÇÃO — FORA DO SIMPLES NACIONAL
A30: Tributo | B30: Lucro Presumido | C30: Lucro Real | D30: Observação
A31: PIS + COFINS | B31: 0.0365 | C31: 0.0925 | D31: No Real são não cumulativos, com crédito sobre malha, energia, frete e insumos.
A32: IRPJ | B32: presunção 8,8% × 15% | C32: 34% sobre o lucro | D32: A presunção subiu 10% sobre a receita acima de R$ 5 mi/ano (IN RFB 2.306/2026).
A33: CSLL | B33: presunção 13,2% × 9% | C33: incluso nos 34% | D33: —
A34: Federal efetivo sobre receita | B34: 0.0704 | C34: variável | D34: No Presumido é fixo; no Real depende da margem e dos créditos.
A35: ICMS líquido de créditos | B35: 0.07 | C35: 0.07 | D35: ESTIMATIVA. Depende do estado, do regime especial e do perfil de créditos.
A36: Regra prática: se a margem líquida real da indústria está abaixo de 8%, o Lucro Presumido está fazendo a empresa pagar imposto sobre lucro que não existe. A comparação precisa ser refeita pelo contador com os números fechados de 2026, separando receita B2B de receita direta.
A38: DEVOLUÇÃO E MÍDIA — REFERÊNCIAS DE 2026
A39: Indicador | B39: Faixa | C39: Fonte | D39: Observação
A40: Devolução em moda | B40: 30% a 40% | C40: E-commerce Brasil 2026 | D40: Tamanho errado responde por mais da metade dos casos.
A41: Devolução em vestidos | B41: até 50% | C41: Operações específicas | D41: Vestidos e alfaiataria são as categorias de maior risco.
A42: Custo por devolução | B42: R$ 35 a R$ 65 | C42: Logística reversa | D42: Frete reverso mais recebimento, conferência e reintegração.
A43: CPM Meta — feed | B43: R$ 15 a R$ 35 | C43: Benchmarks Brasil 2026 | D43: Reels e Stories saem entre R$ 8 e R$ 20.
A44: CPC Google — moda | B44: R$ 1,50 a R$ 4,00 | C44: Benchmarks Brasil 2026 | D44: —
A45: ROAS mediano — e-commerce | B45: 1,93x | C45: Benchmarks por indústria | D45: Mediana de mercado em Meta Ads.
...
